Workbook

Sheet Summary
A1: Hotel Berlin, Berlin – FAQ reconciliation
A2: Existing 47 FAQs (from the repo and live DB, which match exactly) reconciled against the 38 triaged from the chatbot export.
A4: Rule used: existing published content is never overwritten. Workbook entries either fill a gap (Net new), arrive as a proposed diff on an existing record (Merge into existing), or are retired because the existing answer is better (Existing wins).
A6: Counts
A7: Existing FAQs | B7: =COUNTA('Existing 47'!A2:A48) -> 47
A8: …of which merge into another record | B8: =COUNTIF('Existing 47'!H2:H48,"Merge into*") -> 7
A9: …surviving existing records | B9: =SUM('Existing 47'!K2:K48) -> 40
A10: Workbook FAQs – existing wins (retired) | B10: =COUNTIF('Workbook 38'!D2:D39,"Existing wins*") -> 7
A11: Workbook FAQs – merge into existing (diffs) | B11: =COUNTIF('Workbook 38'!D2:D39,"Merge into existing") -> 11
A12: Workbook FAQs – net new | B12: =COUNTIF('Workbook 38'!D2:D39,"Net new") -> 20
A13: Total FAQs after reconcile | B13: =B9+B12 -> 60
A14: Existing records marked CONFLICT | B14: =COUNTIF('Existing 47'!H2:H48,"*CONFLICT*") -> 6
A15: Fact conflicts to put to the hotel | B15: =COUNTA(Conflicts!A2:A10) -> 9
A16: Typed facts in existing EN answers (token candidates) | B16: =SUM('Existing 47'!L2:L48) -> 36
A17: Gaps still fully open | B17: =COUNTIF('Gaps (updated)'!C2:C18,"Still open") -> 7
A19: Sheets
A20: Existing 47 – each current FAQ with proposed audience, topic, priority, action and merge group.
A21: Workbook 38 – what happens to each triaged FAQ.
A22: Conflicts – where existing answers and the chatbot disagree; these need the hotel.
A23: Merge groups – duplicate pairs collapsed into one 'both' record (old #anchors must keep working).
A24: Category map – old 17 categories → new topics. Topics (revised) – 24 topics with live counts.
A25: Typed facts → tokens – the hard-typed facts (73 rows across EN+DE, 36 in EN) and what they become. Gaps (updated) – gap list after the existing set is counted.

Sheet Existing 47
A1: Slug | B1: Context now | C1: Category now | D1: Audience (proposed) | E1: Topic | F1: Topic 2 | G1: Priority | H1: Proposed action | I1: Merge group | J1: Workbook match | K1: Survives? (1/0) | L1: Typed facts (EN) | M1: Question (EN) | N1: Answer (EN) | O1: Notes
A2: check-in-time | B2: prospect | C2: general | D2: both | E2: checkin-checkout | G2: 1 | H2: Survivor + diff | I2: G1 | J2: F01 | K2: =IF(LEFT(H2,10)="Merge into",0,1) -> 1 | L2: 3 | M2: What time can I check in at Hotel Berlin, Berlin? | N2: Check-in at Hotel Berlin, Berlin is from 15:00. Early check-in from 06:00 is available for €30 if a room is ready — or book the night before for guaranteed early access. | O2: Add late-arrival line from F01. Early check-in €30 from 06:00 exists only here (closes Gap G10). Absorbs guest-checkin.
A3: parking | B3: prospect | C3: general | D3: both | E3: parking | F3: getting-here | G3: 1 | H3: Survivor + diff | I3: G2 | J3: F06 | K3: =IF(LEFT(H3,10)="Merge into",0,1) -> 1 | L3: 2 | M3: Is there parking at Hotel Berlin, Berlin? | N3: Yes. Hotel Berlin, Berlin has underground parking with over 200 spaces. €4 per hour, maximum €25 per day. EV charging is available nearby. | O3: Absorbs guest-parking (208 spaces, 1.80 m, access street). C5: 'underground only' vs workbook 'outdoor and underground'; 'EV nearby' vs guest-ev-charging.
A4: pet-policy | B4: prospect | C4: general | D4: both | E4: pets | G4: 1 | H4: Survivor + diff | I4: G3 | J4: F13 | K4: =IF(LEFT(H4,10)="Merge into",0,1) -> 1 | L4: 1 | M4: Are pets allowed at Hotel Berlin, Berlin? | N4: Yes, pets are welcome at Hotel Berlin, Berlin. There is a charge of €30 per night. Pets are also welcome at breakfast. | O4: Absorbs guest-dogs. Add 'tell us in advance'. C9: 'per night' vs guest-dogs 'per day'; pets vs dogs only.
A5: airport-transfer | B5: prospect | C5: general | D5: both | E5: getting-here | G5: 1 | H5: Keep – CONFLICT | J5: F07 | K5: =IF(LEFT(H5,10)="Merge into",0,1) -> 1 | L5: 0 | M5: How do I get to Hotel Berlin, Berlin from BER airport? | N5: Take the RE7 or RB14 to Zoologischer Garten, then Bus 100 to Lützowplatz — right outside the hotel. Around 45–55 minutes total. | O5: C1: RE7/RB14 + Bus 100 vs workbook RE20/FEX + 106/M46. Verify against BVG before publishing either.
A6: cancellation-flexible | B6: prospect | C6: rooms-booking | D6: prospect | E6: cancellation | G6: 1 | H6: Keep | K6: =IF(LEFT(H6,10)="Merge into",0,1) -> 1 | L6: 2 | M6: What is the cancellation policy for a flexible rate? | N6: Flexible rate bookings at Hotel Berlin, Berlin can be cancelled free of charge until 18:00 on the day of arrival. A late cancellation or no-show is charged at 90% of the first night. | O6: Covers the flexible rate only; other rates unanswered (Gap G01 partly closed). Needs tokens for 18:00 and 90 %.
A7: breakfast-times | B7: prospect | C7: dining | D7: both | E7: breakfast | F7: dining | G7: 1 | H7: Survivor + diff – CONFLICT | I7: G4 | J7: F08, F09, F10 | K7: =IF(LEFT(H7,10)="Merge into",0,1) -> 1 | L7: 2 | M7: What are the breakfast times at Hotel Berlin? | N7: Breakfast is served daily from 06:30 to 10:00. It is a full buffet with vegan options available. | O7: C6: says 'daily 06:30–10:00' while guest-breakfast says Sat/Sun to 11:00. Absorbs guest-breakfast. Claims vegan options – confirm.
A8: guest-checkin | B8: guest | C8: arrival-departure | D8: both | E8: checkin-checkout | G8: 1 | H8: Merge into check-in-time | I8: G1 | J8: F01 | K8: =IF(LEFT(H8,10)="Merge into",0,1) -> 0 | L8: 1 | M8: What time is check-in? | N8: Check-in is from 15:00. If you arrive earlier, Guest Care can store your luggage until your room is ready. | O8: Same 15:00; luggage sentence already lives in guest-luggage.
A9: guest-checkout | B9: guest | C9: arrival-departure | D9: both | E9: checkin-checkout | G9: 1 | H9: Keep + diff – CONFLICT | J9: F04, F05 | K9: =IF(LEFT(H9,10)="Merge into",0,1) -> 1 | L9: 1 | M9: What time is check-out? | N9: Check-out is by 12:00. Later check-out is arranged with the lobby hosts — ask on the morning you leave. | O9: C3: 'ask lobby hosts on the day' vs workbook 'late check-out to 15:00 for €30, ask in advance'. Key-drop (F05) not covered.
A10: guest-luggage | B10: guest | C10: arrival-departure | D10: both | E10: checkin-checkout | G10: 2 | H10: Keep (wins over F03) | J10: F03 | K10: =IF(LEFT(H10,10)="Merge into",0,1) -> 1 | L10: 0 | M10: Where can I store luggage before check-in or after check-out? | N10: Luggage storage is available before check-in and after check-out. Ask at the Guest Care Center beside the lobby. | O10: Covers before check-in AND after check-out (closes Gap G09).
A11: guest-lost-and-found | B11: guest | C11: arrival-departure | D11: guest | E11: lost-property | F11: contact | G11: 2 | H11: Keep + diff | J11: F34 | K11: =IF(LEFT(H11,10)="Merge into",0,1) -> 1 | L11: 1 | M11: Where is lost property? | N11: Lost property is handled by the Guest Care Center beside the lobby, 24/7. | O11: Add the online form link once the URL is confirmed.
A12: guest-do-not-disturb | B12: guest | C12: arrival-departure | D12: guest | E12: in-room | G12: 3 | H12: Keep | K12: =IF(LEFT(H12,10)="Merge into",0,1) -> 1 | L12: 0 | M12: How does the do-not-disturb sign work? | N12: Use the do-not-disturb sign on your door. Housekeeping will skip the room until you take it down.
A13: guest-wifi | B13: guest | C13: in-room | D13: guest | E13: wifi | F13: in-room | G13: 1 | H13: Keep (wins over F12) | J13: F12 | K13: =IF(LEFT(H13,10)="Merge into",0,1) -> 1 | L13: 0 | M13: How do I connect to the hotel WiFi? | N13: Ask at the Guest Care Center beside the lobby for the current network details. They will get you online. | O13: Deliberately omits SSID/password – matches the standing 'do not publish' instruction. F12 retired; WiFi details stay HOLD.
A14: guest-minibar | B14: guest | C14: in-room | D14: both | E14: in-room | G14: 3 | H14: Keep | K14: =IF(LEFT(H14,10)="Merge into",0,1) -> 1 | L14: 1 | M14: Is there a minibar? | N14: The minibar is empty on purpose — use it as your own fridge. Snacks and drinks are at Wundermart in the lobby, 24/7.
A15: guest-safe | B15: guest | C15: in-room | D15: guest | E15: in-room | G15: 3 | H15: Keep | K15: =IF(LEFT(H15,10)="Merge into",0,1) -> 1 | L15: 0 | M15: How do I use the room safe? | N15: Room safes are set up through the Guest Care Center beside the lobby. | O15: Closes Gap G14.
A16: guest-housekeeping | B16: guest | C16: in-room | D16: both | E16: in-room | F16: sustainability | G16: 2 | H16: Keep – CONFLICT | J16: F20 | K16: =IF(LEFT(H16,10)="Merge into",0,1) -> 1 | L16: 0 | M16: How often is housekeeping? | N16: Housekeeping is daily. Bed linen is changed every three days. | O16: C2: 'daily, linen every 3 days' vs workbook 'every second day, Green Hero opt-out'.
A17: guest-iron | B17: guest | C17: in-room | D17: guest | E17: services | F17: in-room | G17: 3 | H17: Keep (wins over F23) | J17: F23 | K17: =IF(LEFT(H17,10)="Merge into",0,1) -> 1 | L17: 0 | M17: Can I get an iron? | N17: Yes — dial 9 from the room phone and Guest Care will bring an iron. | O17: 'Dial 9 from the room phone' – answers the phone-number question for this FAQ.
A18: guest-adapter | B18: guest | C18: in-room | D18: guest | E18: services | F18: in-room | G18: 3 | H18: Keep (wins over F22) | J18: F22 | K18: =IF(LEFT(H18,10)="Merge into",0,1) -> 1 | L18: 1 | M18: Where can I get a plug adapter? | N18: Adapters are in Wundermart in the lobby, 24/7, card payment. | O18: Confirms adapters at Wundermart, 24/7, card – resolves F22's [CONFIRM].
A19: guest-air-conditioning | B19: guest | C19: in-room | D19: both | E19: in-room | G19: 2 | H19: Keep | K19: =IF(LEFT(H19,10)="Merge into",0,1) -> 1 | L19: 0 | M19: Can I adjust the air conditioning? | N19: Yes. The room climate can be adjusted by about ±3 °C. | O19: Closes Gap G05 (±3 °C).
A20: guest-tap-water | B20: guest | C20: in-room | D20: both | E20: in-room | G20: 3 | H20: Keep | K20: =IF(LEFT(H20,10)="Merge into",0,1) -> 1 | L20: 0 | M20: Is the tap water drinkable? | N20: Yes. Berlin tap water is drinking water.
A21: guest-phone-rates | B21: guest | C21: in-room | D21: guest | E21: in-room | G21: 3 | H21: Keep | K21: =IF(LEFT(H21,10)="Merge into",0,1) -> 1 | L21: 2 | M21: What does the room phone cost? | N21: Calls in Germany are €0.40 per minute. International calls are €0.80–€3.20 per minute. | O21: Typed rates → tokens. Stale risk.
A22: guest-card-only | B22: guest | C22: money-payment | D22: both | E22: payment | G22: 1 | H22: Survivor + diff | I22: G5 | J22: F32 | K22: =IF(LEFT(H22,10)="Merge into",0,1) -> 1 | L22: 0 | M22: Can I pay with cash? | N22: No. The hotel is card and contactless only — no cash. | O22: Absorbs guest-dining-card-only. Add accepted methods only once Giropay is verified.
A23: guest-atm | B23: guest | C23: money-payment | D23: guest | E23: payment | G23: 3 | H23: Keep | K23: =IF(LEFT(H23,10)="Merge into",0,1) -> 1 | L23: 0 | M23: Where is the nearest ATM? | N23: Commerzbank has an ATM across the street from the hotel. | O23: Third-party fact (Commerzbank across the street) – stale risk.
A24: guest-currency-exchange | B24: guest | C24: money-payment | D24: guest | E24: payment | G24: 3 | H24: Keep | K24: =IF(LEFT(H24,10)="Merge into",0,1) -> 1 | L24: 0 | M24: Can I change money at the hotel? | N24: There is no bureau de change in the hotel. The nearest is at Bahnhof Zoologischer Garten. | O24: Third-party fact – stale risk.
A25: guest-medical-on-call | B25: guest | C25: health-emergency | D25: guest | E25: health-safety | G25: 2 | H25: Keep | K25: =IF(LEFT(H25,10)="Merge into",0,1) -> 1 | L25: 2 | M25: Who do I call for a doctor out of hours? | N25: The on-call medical service is 116 117. For emergencies call 112.
A26: guest-emergency | B26: guest | C26: health-emergency | D26: guest | E26: health-safety | G26: 2 | H26: Survivor (review) | I26: G7 | K26: =IF(LEFT(H26,10)="Merge into",0,1) -> 1 | L26: 2 | M26: What is the emergency number? | N26: Call 112 for fire, ambulance, or police emergency. Trained staff are in the building around the clock. | O26: Absorbs guest-staff-24-7 (same sentence).
A27: guest-gp | B27: guest | C27: health-emergency | D27: guest | E27: health-safety | G27: 3 | H27: Keep | K27: =IF(LEFT(H27,10)="Merge into",0,1) -> 1 | L27: 0 | M27: Is there a GP nearby? | N27: There is a GP at Nollendorfplatz, about a 10-minute walk. | O27: Third-party fact – stale risk.
A28: guest-pharmacy-nollendorf | B28: guest | C28: health-emergency | D28: guest | E28: health-safety | G28: 3 | H28: Survivor + diff | I28: G6 | K28: =IF(LEFT(H28,10)="Merge into",0,1) -> 1 | L28: 0 | M28: Where is the nearest pharmacy? | N28: Quartier Apotheke Nolleturm, Nollendorfplatz 3–4. There is also a pharmacy at Wittenbergplatz, Bayreuther Straße 44. | O28: Absorbs the Wittenbergplatz pharmacy (already named in this answer).
A29: guest-pharmacy-wittenbergplatz | B29: guest | C29: health-emergency | D29: guest | E29: health-safety | G29: 3 | H29: Merge into guest-pharmacy-nollendorf | I29: G6 | K29: =IF(LEFT(H29,10)="Merge into",0,1) -> 0 | L29: 0 | M29: Is there a pharmacy at Wittenbergplatz? | N29: Yes — Apotheke am Wittenbergplatz, Bayreuther Straße 44.
A30: guest-babysitting | B30: guest | C30: health-emergency | D30: both | E30: services | G30: 3 | H30: Keep | K30: =IF(LEFT(H30,10)="Merge into",0,1) -> 1 | L30: 0 | M30: Can the hotel arrange babysitting? | N30: Yes. Guest Care can book a babysitting agency for you. | O30: Partly answers Gap G03 (children).
A31: guest-staff-24-7 | B31: guest | C31: health-emergency | D31: guest | E31: health-safety | G31: 3 | H31: Merge into guest-emergency | I31: G7 | K31: =IF(LEFT(H31,10)="Merge into",0,1) -> 0 | L31: 1 | M31: Is there staff in the building at night? | N31: Yes. Trained staff are in the hotel around the clock.
A32: guest-parking | B32: guest | C32: getting-around | D32: both | E32: parking | G32: 1 | H32: Merge into parking | I32: G2 | J32: F06 | K32: =IF(LEFT(H32,10)="Merge into",0,1) -> 0 | L32: 2 | M32: How does parking work? | N32: The underground garage has 208 spaces, €4 per hour, max €25 per day. Entry height is 1.80 m. Access is from Karl-Heinrich-Ulrichs-Straße.
A33: guest-ev-charging | B33: guest | C33: getting-around | D33: both | E33: parking | G33: 2 | H33: Keep | K33: =IF(LEFT(H33,10)="Merge into",0,1) -> 1 | L33: 0 | M33: Is there EV charging? | N33: Yes. 8 AC points, up to 22 kW, Type 2. | O33: Closes Gap G13. Conflicts with prospect 'EV charging nearby' (C5).
A34: guest-bike-garage | B34: guest | C34: getting-around | D34: both | E34: bikes | G34: 2 | H34: Keep (wins over F30) | J34: F30, F31 | K34: =IF(LEFT(H34,10)="Merge into",0,1) -> 1 | L34: 0 | M34: Can I store a bike? | N34: Yes. There is a bike garage with e-bike charging. | O34: Includes e-bike charging. Bike rental (F31) is not covered.
A35: guest-car-rental | B35: guest | C35: getting-around | D35: guest | E35: getting-around | G35: 3 | H35: Keep | K35: =IF(LEFT(H35,10)="Merge into",0,1) -> 1 | L35: 0 | M35: Where can I rent a car? | N35: StarCar is at Schillstraße 9, about a minute away. Avis, Hertz and Europcar are at Tauentzienstraße 9–11, about 10 minutes. | O35: Third-party fact – stale risk.
A36: guest-taxi | B36: guest | C36: getting-around | D36: guest | E36: getting-around | G36: 3 | H36: Keep | K36: =IF(LEFT(H36,10)="Merge into",0,1) -> 1 | L36: 0 | M36: How do I get a taxi? | N36: Ask the Guest Care Center beside the lobby to call one. There is a rank at Lützowplatz.
A37: guest-jogging | B37: guest | C37: getting-around | D37: guest | E37: getting-around | F37: wellness | G37: 3 | H37: Keep | K37: =IF(LEFT(H37,10)="Merge into",0,1) -> 1 | L37: 0 | M37: Where can I go for a run? | N37: Tiergarten is the closest loop. Guest Care can point you to the canal paths as well.
A38: guest-dogs | B38: guest | C38: house-rules | D38: both | E38: pets | G38: 1 | H38: Merge into pet-policy | I38: G3 | J38: F13 | K38: =IF(LEFT(H38,10)="Merge into",0,1) -> 0 | L38: 1 | M38: Are dogs allowed? | N38: Yes. Dogs are €30 per day.
A39: guest-nonsmoking | B39: guest | C39: house-rules | D39: both | E39: house-rules | G39: 2 | H39: Keep | K39: =IF(LEFT(H39,10)="Merge into",0,1) -> 1 | L39: 1 | M39: Can I smoke in the hotel? | N39: No. This is a non-smoking hotel. Smoking in the room incurs a €250 cleaning fee. | O39: Closes Gap G06. €250 fee → token.
A40: guest-gym | B40: guest | C40: house-rules | D40: both | E40: wellness | G40: 2 | H40: Keep (wins over F28) | J40: F28 | K40: =IF(LEFT(H40,10)="Merge into",0,1) -> 1 | L40: 1 | M40: When is the gym open? | N40: The gym is open 24/7 for hotel guests.
...

Sheet Workbook 38
A1: ID | B1: Topic | C1: Question (EN) | D1: Disposition | E1: Existing slug(s) | F1: What to take from the workbook version | G1: Conflict | H1: Status after reconcile
A2: F01 | B2: checkin-checkout | C2: What time can I check in, and what if I arrive late? | D2: Merge into existing | E2: check-in-time, guest-checkin | F2: Late-arrival wording; check Guest Care vs 'reception' | G2: C7 | H2: Ready
A3: F02 | B3: checkin-checkout | C3: Can I check in online? | D3: Net new | H3: Needs confirm
A4: F03 | B4: checkin-checkout | C4: Can I leave my luggage before check-in? | D4: Existing wins – retire workbook version | E4: guest-luggage | F4: Nothing – existing also covers after check-out | H4: Retired
A5: F04 | B5: checkin-checkout | C5: What time is check-out, and can I stay longer? | D5: Merge into existing | E5: guest-checkout | F5: Late check-out terms, if the hotel confirms them | G5: C3 | H5: HOLD
A6: F05 | B6: checkin-checkout | C6: Do I need to leave my key in the room at check-out? | D6: Net new | F6: Check-out terminals / key box | G6: C3 | H6: Needs confirm
A7: F06 | B7: parking | C7: Can I reserve parking, and how much does it cost? | D7: Merge into existing | E7: parking, guest-parking | F7: 'No reservation needed'; outdoor vs underground | G7: C5 | H7: Needs confirm
A8: F07 | B8: getting-here | C8: Do you offer an airport transfer, and how do I get to the hotel from the airport? | D8: Merge into existing | E8: airport-transfer | F8: Alternative route, only if BVG confirms | G8: C1 | H8: HOLD
A9: F08 | B9: breakfast | C9: When is breakfast served? | D9: Merge into existing | E9: breakfast-times, guest-breakfast | F9: Weekday vs weekend + holiday split | G9: C6 | H9: Needs confirm
A10: F09 | B10: breakfast | C10: Where is the breakfast restaurant? | D10: Net new | H10: Ready
A11: F10 | B11: breakfast | C11: Can I book breakfast after I've booked my room, and what does it cost? | D11: Merge into existing | E11: guest-breakfast | F11: 'Can be added later' wording; child price 11.50 vs 12 | G11: C6 | H11: Needs confirm
A12: F11 | B12: dining | C12: Do you have room service? | D12: Merge into existing | E12: guest-room-service | F12: Delivery recommendations – if confirmed | G12: C4 | H12: HOLD
A13: F12 | B13: wifi | C13: How do I connect to the WiFi? | D13: Existing wins – retire workbook version | E13: guest-wifi | F13: Nothing – SSID stays unpublished | H13: HOLD
A14: F13 | B14: pets | C14: Can I bring my dog? | D14: Merge into existing | E14: pet-policy, guest-dogs | F14: Advance-notice line; other pets? | G14: C9 | H14: Needs confirm
A15: F14 | B15: rooms | C15: Can I request a quiet room? | D15: Net new | H15: Ready
A16: F15 | B16: rooms | C16: Do any rooms have a balcony? | D16: Net new | H16: Ready
A17: F16 | B17: rooms | C17: Which are the largest rooms? | D17: Net new | H17: Needs confirm
A18: F17 | B18: rooms | C18: How do I find my room? | D18: Net new | H18: HOLD
A19: F18 | B19: in-room | C19: Do I need my key card to use the lifts? | D19: Net new | H19: Ready
A20: F19 | B20: in-room | C20: Is there a Nespresso machine in the room? | D20: Net new | H20: HOLD
A21: F20 | B21: in-room | C21: Is my room cleaned every day? | D21: Merge into existing | E21: guest-housekeeping | F21: Green Hero opt-out, if confirmed | G21: C2 | H21: HOLD
A22: F21 | B22: in-room | C22: Can I connect my own streaming stick (e.g. Amazon Fire TV) to the TV? | D22: Net new | H22: Needs confirm
A23: F22 | B23: services | C23: Where can I get a power adapter? | D23: Existing wins – retire workbook version | E23: guest-adapter | F23: Nothing | H23: Retired
A24: F23 | B24: services | C24: Can I borrow an iron or an ironing board? | D24: Existing wins – retire workbook version | E24: guest-iron | F24: Nothing – 'dial 9' answers it | H24: Retired
A25: F24 | B25: services | C25: Do you offer a laundry service? | D25: Net new | H25: Needs confirm
A26: F25 | B26: services | C26: Can you print a document for me? | D26: Net new | E26: guest-business-center (?) | F26: Check whether the business center is the printing answer | H26: Needs confirm
A27: F26 | B27: wellness | C27: What are the sauna opening hours? | D27: Existing wins – retire workbook version | E27: guest-sauna | F27: Nothing – hours stay HOLD | G27: C8 | H27: HOLD
A28: F27 | B28: wellness | C28: Is the sauna clothing-free? | D28: Net new | E28: guest-sauna (related) | H28: Ready
A29: F28 | B29: wellness | C29: Who can use the gym? | D29: Existing wins – retire workbook version | E29: guest-gym | F29: Nothing | H29: Retired
A30: F29 | B30: activities | C30: Is there still a fingerboard park? | D30: Net new | H30: HOLD
A31: F30 | B31: bikes | C31: Can I store my own bike at the hotel? | D31: Existing wins – retire workbook version | E31: guest-bike-garage | F31: Nothing | H31: Retired
A32: F31 | B32: bikes | C32: Can I rent a bike? | D32: Net new | E32: guest-bike-garage (related) | H32: Needs confirm
A33: F32 | B33: payment | C33: Can I pay without a credit card? | D33: Merge into existing | E33: guest-card-only | F33: Accepted payment methods, after Giropay check | H33: Needs confirm
A34: F33 | B34: loyalty | C34: Do you have a loyalty programme? | D34: Net new | H34: Needs confirm
A35: F34 | B35: lost-property | C35: I lost something at the hotel. What should I do? | D35: Merge into existing | E35: guest-lost-and-found | F35: Online form link | H35: Needs confirm
A36: F35 | B36: meetings | C36: How do I book a meeting room? | D36: Net new | H36: Ready
A37: F36 | B37: contact | C37: How can I contact the hotel? | D37: Net new | E37: guest-care-center (related) | G37: C7 | H37: HOLD
A38: F37 | B38: payment | C38: How do I change a prepayment invoice? | D38: Net new | H38: Ready
A39: F38 | B39: sustainability | C39: Who is the contact for sustainability? | D39: Net new | H39: Ready

Sheet Conflicts
A1: ID | B1: Topic | C1: Existing records | D1: Existing says | E1: Chatbot / workbook says | F1: Default trust | G1: Question for the hotel | H1: Affects
A2: C1 | B2: Airport route | C2: airport-transfer | D2: RE7 or RB14 to Zoologischer Garten, then Bus 100 to Lützowplatz (45–55 min). | E2: F07: RE20 or FEX to Südkreuz, then Bus 106 to Lützowplatz; or M46 to Schillstraße. | F2: Existing (written, specific) – but check both against current BVG/VBB. | G2: Which route do you actually send BER guests on? | H2: F07, airport-transfer
A3: C2 | B3: Housekeeping frequency | C3: guest-housekeeping | D3: Housekeeping is daily; bed linen changed every 3 days. | E3: F20: room cleaned every second day; Green Hero opt-out. | F3: Existing. | G3: What is the real cleaning schedule, and does the Green Hero programme exist? | H3: F20, sustainability FAQs
A4: C3 | B4: Late check-out / early check-in | C4: guest-checkout, check-in-time | D4: Later check-out arranged with the lobby hosts on the morning. Early check-in from 06:00 for €30 if a room is ready. | E4: F04: late check-out to 15:00 for €30, subject to availability, ask in advance. | F4: Existing – but ask whether the €30 / 15:00 late check-out is real. | G4: Is there a fixed late check-out fee and cut-off? Is early check-in €30 from 06:00 still current? | H4: F04, F05
A5: C4 | B5: Room service | C5: guest-room-service | D5: No room service – collect food and drinks at the bar. | E5: F11: no room service; reception recommends delivery services; guests may take breakfast/dinner from the restaurant to the room. | F5: Existing. | G5: Can guests take restaurant food up to the room? Does reception recommend delivery services? | H5: F11
A6: C5 | B6: Parking details | C6: parking, guest-parking, guest-ev-charging | D6: Underground garage only; 'over 200' (prospect) vs 208 (guest); entry 1.80 m; access via Karl-Heinrich-Ulrichs-Straße; prospect says 'EV charging available nearby', guest says 8 AC points, up to 22 kW, Type 2. | E6: F06: 208 spaces, outdoor and underground, no reservation, max height 1.80 m. | F6: Existing guest version. | G6: Are there outdoor spaces? Is EV charging on site (8 points) or nearby? | H6: F06
A7: C6 | B7: Breakfast | C7: breakfast-times, guest-breakfast | D7: Prospect: daily 06:30–10:00, vegan options. Guest: 06:30–10:00, Sat/Sun to 11:00; €23 adults, €12 from age 6. | E7: F08/F10: Mon–Fri to 10:00; weekends AND public holidays to 11:00; €23; children 6+ €11.50. | F7: Mixed – the existing records disagree with each other. | G7: Weekend/holiday times? Child price €12 or €11.50? Vegan options claim? | H7: F08, F10
A8: C7 | B8: 'Guest Care Center' vs 'reception' | C8: all guest FAQs | D8: Existing answers send people to the Guest Care Center beside the lobby (and to 'lobby hosts'); room phone: dial 9. | E8: Chatbot answers say 'reception' / 'reception team' throughout. | F8: Existing – it matches how the hotel names its own service. | G8: What do you call the desk: Guest Care Center, reception, lobby hosts? One word site-wide. | H8: F01, F02, F04, F05, F13, F23, F25, F36
A9: C8 | B9: Sauna | C9: guest-sauna | D9: On request, 45 minutes' notice; book a slot via Guest Care. No clock hours. | E9: F26: daily 18:00–23:00, on request June–August; notice 45 minutes. | F9: Existing – and this is the known conflict (launch checklist 3.13). | G9: Which schedule is true? | H9: F26
A10: C9 | B10: Pets vs dogs; per night vs per day | C10: pet-policy, guest-dogs | D10: Prospect: pets welcome, €30 per night, welcome at breakfast. Guest: dogs €30 per day. | E10: F13: dogs welcome, €30 per night, tell us in advance; 'pets such as dogs'. | F10: Existing, with 'per night'. | G10: Are other pets allowed? Per night or per day? | H10: F13, G16

Sheet Merge groups
A1: Group | B1: Survivor slug | C1: Absorbed slug | D1: Audience after | E1: Alias needed?
A2: G1 | B2: check-in-time | C2: guest-checkin | D2: both | E2: Yes – keep the old `#slug` anchor working
A3: G2 | B3: parking | C3: guest-parking | D3: both | E3: Yes – keep the old `#slug` anchor working
A4: G3 | B4: pet-policy | C4: guest-dogs | D4: both | E4: Yes – keep the old `#slug` anchor working
A5: G4 | B5: breakfast-times | C5: guest-breakfast | D5: both | E5: Yes – keep the old `#slug` anchor working
A6: G5 | B6: guest-card-only | C6: guest-dining-card-only | D6: both | E6: Yes – keep the old `#slug` anchor working
A7: G6 | B7: guest-pharmacy-nollendorf | C7: guest-pharmacy-wittenbergplatz | D7: guest | E7: Yes – keep the old `#slug` anchor working
A8: G7 | B8: guest-emergency | C8: guest-staff-24-7 | D8: guest | E8: Yes – keep the old `#slug` anchor working

Sheet Category map
A1: Old category | B1: New topic(s) | C1: Existing records using it | D1: Note
A2: rooms-booking | B2: rooms | C2: =COUNTIF('Existing 47'!$C$2:$C$48,A2) -> 1 | D2: Prospect. 1 record (cancellation-flexible) goes to `cancellation` instead.
A3: checkin-checkout | B3: checkin-checkout | C3: =COUNTIF('Existing 47'!$C$2:$C$48,A3) -> 0 | D3: Prospect. No records yet.
A4: dining | B4: dining | C4: =COUNTIF('Existing 47'!$C$2:$C$48,A4) -> 5 | D4: Used by BOTH audiences in the data (guest A–Z reuses it). Breakfast records → `breakfast`.
A5: meetings | B5: meetings | C5: =COUNTIF('Existing 47'!$C$2:$C$48,A5) -> 0 | D5: Prospect. No records yet.
A6: accessibility | B6: accessibility | C6: =COUNTIF('Existing 47'!$C$2:$C$48,A6) -> 0 | D6: NEW topic. No records yet.
A7: getting-here | B7: getting-here | C7: =COUNTIF('Existing 47'!$C$2:$C$48,A7) -> 0 | D7: Prospect. No records yet (airport-transfer sits in `general`).
A8: pets-parking | B8: pets / parking | C8: =COUNTIF('Existing 47'!$C$2:$C$48,A8) -> 0 | D8: Split into two topics. No records use it.
A9: general | B9: by record | C9: =COUNTIF('Existing 47'!$C$2:$C$48,A9) -> 4 | D9: Catch-all: check-in-time→checkin-checkout, parking→parking, pet-policy→pets, airport-transfer→getting-here.
A10: wifi-tech | B10: wifi | C10: =COUNTIF('Existing 47'!$C$2:$C$48,A10) -> 0 | D10: Guest. No records use it (guest-wifi is `in-room`).
A11: guest-services | B11: services | C11: =COUNTIF('Existing 47'!$C$2:$C$48,A11) -> 0 | D11: Guest. No records use it.
A12: neighbourhood-guest | B12: getting-around / health-safety | C12: =COUNTIF('Existing 47'!$C$2:$C$48,A12) -> 0 | D12: Guest. No records use it; neighbourhood items are spread across new topics.
A13: arrival-departure | B13: checkin-checkout | C13: =COUNTIF('Existing 47'!$C$2:$C$48,A13) -> 5 | D13: Lost property → `lost-property`; do-not-disturb → `in-room`.
... A18: house-rules | B18: by record | C18: =COUNTIF('Existing 47'!$C$2:$C$48,A18) -> 7 | D18: Dogs → pets; non-smoking → NEW `house-rules`; gym/sauna → wellness; business center → services; Guest Care → contact; room service → dining.

Sheet Topics (revised)
A1: Topic slug | B1: Label (EN) | C1: Label (DE) | D1: Covers | E1: Existing (surviving) | F1: Workbook net new | G1: FAQs touching this topic (primary + secondary)
A2: checkin-checkout | B2: Check-in & check-out | C2: Check-in & Check-out | D2: Times, online check-in, luggage, late check-out | E2: =COUNTIFS('Existing 47'!$E$2:$E$48,A2,'Existing 47'!$K$2:$K$48,1)+COUNTIFS('Existing 47'!$F$2:$F$48,A2,'Existing 47'!$K$2:$K$48,1) -> 3 | F2: =COUNTIFS('Workbook 38'!$B$2:$B$39,A2,'Workbook 38'!$D$2:$D$39,"Net new") -> 2 | G2: =E2+F2 -> 5
A3: getting-here | B3: Getting here | C3: Anreise | D3: Airport, trains, public transport | E3: =COUNTIFS('Existing 47'!$E$2:$E$48,A3,'Existing 47'!$K$2:$K$48,1)+COUNTIFS('Existing 47'!$F$2:$F$48,A3,'Existing 47'!$K$2:$K$48,1) -> 2 | F3: =COUNTIFS('Workbook 38'!$B$2:$B$39,A3,'Workbook 38'!$D$2:$D$39,"Net new") -> 0 | G3: =E3+F3 -> 2
A4: parking | B4: Parking | C4: Parken | D4: Spaces, prices, height limits | E4: =COUNTIFS('Existing 47'!$E$2:$E$48,A4,'Existing 47'!$K$2:$K$48,1)+COUNTIFS('Existing 47'!$F$2:$F$48,A4,'Existing 47'!$K$2:$K$48,1) -> 2 | F4: =COUNTIFS('Workbook 38'!$B$2:$B$39,A4,'Workbook 38'!$D$2:$D$39,"Net new") -> 0 | G4: =E4+F4 -> 2
A5: breakfast | B5: Breakfast | C5: Frühstück | D5: Times, location, price | E5: =COUNTIFS('Existing 47'!$E$2:$E$48,A5,'Existing 47'!$K$2:$K$48,1)+COUNTIFS('Existing 47'!$F$2:$F$48,A5,'Existing 47'!$K$2:$K$48,1) -> 1 | F5: =COUNTIFS('Workbook 38'!$B$2:$B$39,A5,'Workbook 38'!$D$2:$D$39,"Net new") -> 1 | G5: =E5+F5 -> 2
A6: dining | B6: Eating & drinking | C6: Essen & Trinken | D6: Restaurant, bar, room service | E6: =COUNTIFS('Existing 47'!$E$2:$E$48,A6,'Existing 47'!$K$2:$K$48,1)+COUNTIFS('Existing 47'!$F$2:$F$48,A6,'Existing 47'!$K$2:$K$48,1) -> 4 | F6: =COUNTIFS('Workbook 38'!$B$2:$B$39,A6,'Workbook 38'!$D$2:$D$39,"Net new") -> 0 | G6: =E6+F6 -> 4
A7: rooms | B7: Rooms | C7: Zimmer | D7: Room types, views, balconies, sizes | E7: =COUNTIFS('Existing 47'!$E$2:$E$48,A7,'Existing 47'!$K$2:$K$48,1)+COUNTIFS('Existing 47'!$F$2:$F$48,A7,'Existing 47'!$K$2:$K$48,1) -> 0 | F7: =COUNTIFS('Workbook 38'!$B$2:$B$39,A7,'Workbook 38'!$D$2:$D$39,"Net new") -> 4 | G7: =E7+F7 -> 4
A8: in-room | B8: In your room | C8: Im Zimmer | D8: Equipment and housekeeping | E8: =COUNTIFS('Existing 47'!$E$2:$E$48,A8,'Existing 47'!$K$2:$K$48,1)+COUNTIFS('Existing 47'!$F$2:$F$48,A8,'Existing 47'!$K$2:$K$48,1) -> 11 | F8: =COUNTIFS('Workbook 38'!$B$2:$B$39,A8,'Workbook 38'!$D$2:$D$39,"Net new") -> 3 | G8: =E8+F8 -> 14
A9: wifi | B9: WiFi | C9: WLAN | D9: Connecting and terms | E9: =COUNTIFS('Existing 47'!$E$2:$E$48,A9,'Existing 47'!$K$2:$K$48,1)+COUNTIFS('Existing 47'!$F$2:$F$48,A9,'Existing 47'!$K$2:$K$48,1) -> 1 | F9: =COUNTIFS('Workbook 38'!$B$2:$B$39,A9,'Workbook 38'!$D$2:$D$39,"Net new") -> 0 | G9: =E9+F9 -> 1
A10: wellness | B10: Sauna & fitness | C10: Sauna & Fitness | D10: Sauna, gym | E10: =COUNTIFS('Existing 47'!$E$2:$E$48,A10,'Existing 47'!$K$2:$K$48,1)+COUNTIFS('Existing 47'!$F$2:$F$48,A10,'Existing 47'!$K$2:$K$48,1) -> 3 | F10: =COUNTIFS('Workbook 38'!$B$2:$B$39,A10,'Workbook 38'!$D$2:$D$39,"Net new") -> 1 | G10: =E10+F10 -> 4
A11: activities | B11: Activities | C11: Freizeit | D11: Fingerboard park and other on-site activities | E11: =COUNTIFS('Existing 47'!$E$2:$E$48,A11,'Existing 47'!$K$2:$K$48,1)+COUNTIFS('Existing 47'!$F$2:$F$48,A11,'Existing 47'!$K$2:$K$48,1) -> 0 | F11: =COUNTIFS('Workbook 38'!$B$2:$B$39,A11,'Workbook 38'!$D$2:$D$39,"Net new") -> 1 | G11: =E11+F11 -> 1
A12: services | B12: Services | C12: Services | D12: Laundry, printing, iron, adapters | E12: =COUNTIFS('Existing 47'!$E$2:$E$48,A12,'Existing 47'!$K$2:$K$48,1)+COUNTIFS('Existing 47'!$F$2:$F$48,A12,'Existing 47'!$K$2:$K$48,1) -> 6 | F12: =COUNTIFS('Workbook 38'!$B$2:$B$39,A12,'Workbook 38'!$D$2:$D$39,"Net new") -> 2 | G12: =E12+F12 -> 8
A13: bikes | B13: Bikes | C13: Fahrrad | D13: Storage and rental | E13: =COUNTIFS('Existing 47'!$E$2:$E$48,A13,'Existing 47'!$K$2:$K$48,1)+COUNTIFS('Existing 47'!$F$2:$F$48,A13,'Existing 47'!$K$2:$K$48,1) -> 1 | F13: =COUNTIFS('Workbook 38'!$B$2:$B$39,A13,'Workbook 38'!$D$2:$D$39,"Net new") -> 1 | G13: =E13+F13 -> 2
... A25: house-rules | B25: House rules | C25: Hausregeln | D25: Non-smoking policy and similar | E25: =COUNTIFS('Existing 47'!$E$2:$E$48,A25,'Existing 47'!$K$2:$K$48,1)+COUNTIFS('Existing 47'!$F$2:$F$48,A25,'Existing 47'!$K$2:$K$48,1) -> 1 | F25: =COUNTIFS('Workbook 38'!$B$2:$B$39,A25,'Workbook 38'!$D$2:$D$39,"Net new") -> 0 | G25: =E25+F25 -> 1

Sheet Typed facts → tokens
A1: Fact in existing answers | B1: Where | C1: Proposed token | D1: In workbook Tokens sheet? | E1: Note
A2: 15:00 check-in | B2: check-in-time, guest-checkin | C2: {{checkinTime}} | D2: Yes
A3: 06:00 early check-in | B3: check-in-time | C3: {{earlyCheckinFrom}} | D3: NEW
A4: €30 early check-in | B4: check-in-time | C4: {{earlyCheckinFee}} | D4: NEW | E4: Separate from {{lateCheckoutFee}}.
A5: 12:00 check-out | B5: guest-checkout | C5: {{checkoutTime}} | D5: Yes
A6: €4/hour, €25/day | B6: parking, guest-parking | C6: {{parkingHourly}}, {{parkingDaily}} | D6: Yes | E6: Three records carry these today.
A7: 208 spaces, 1.80 m | B7: guest-parking | C7: {{parkingSpaces}}, {{parkingMaxHeight}} | D7: Yes | E7: Prospect record says 'over 200'.
A8: 06:30–10:00 breakfast | B8: breakfast-times, guest-breakfast | C8: {{breakfastWeekday}} | D8: Yes
A9: Sat/Sun to 11:00 | B9: guest-breakfast | C9: {{breakfastWeekend}} | D9: Yes | E9: Chatbot adds public holidays – C6.
A10: €23 / €12 breakfast | B10: guest-breakfast | C10: {{breakfastPrice}}, {{breakfastPriceChild}} | D10: Yes | E10: €12 vs €11.50 – C6.
A11: €30 pets | B11: pet-policy, guest-dogs | C11: {{petFee}} | D11: Yes | E11: 'per night' vs 'per day' – C9.
A12: 45 minutes sauna notice | B12: guest-sauna | C12: {{saunaNotice}} | D12: Yes | E12: Typed as words, so the scan missed it.
A13: 18:00 cancellation + 90 % no-show | B13: cancellation-flexible | C13: {{cancelFlexibleUntil}}, {{noShowCharge}} | D13: NEW | E13: Belongs with the rate policy, not the hotel global.
A14: €250 smoking fee | B14: guest-nonsmoking | C14: {{smokingFee}} | D14: NEW
A15: Room-phone rates (€0.40; €0.80–3.20) | B15: guest-phone-rates | C15: {{phoneRateDomestic}}, {{phoneRateIntlMin}}, {{phoneRateIntlMax}} | D15: NEW | E15: Low value – could simply stay typed.
A16: 10:00–01:00 Lütze | B16: guest-lutze-hours | C16: — computed — | D16: n/a | E16: Read from venues + venue-time; never a token.
A17: 112 / 116 117 | B17: guest-emergency, guest-medical-on-call | C17: — leave typed — | D17: n/a | E17: National numbers; not hotel-specific.
A18: '24/7' service statements | B18: guest-care-center, guest-gym, guest-wundermart, guest-lost-and-found, guest-minibar, guest-adapter | C18: — leave typed — | D18: n/a | E18: Service promises, not data. Review wording if opening hours change.

Sheet Gaps (updated)
A1: Gap | B1: Missing FAQ | C1: Status now | D1: Covered by
A2: G01 | B2: Cancellation policy | C2: Partly covered | D2: cancellation-flexible (flexible rate only)
A3: G02 | B3: Accessibility | C3: Still open | D3: The `accessibility` category exists but has 0 records
A4: G03 | B4: Children: cots, extra beds, child rates | C4: Partly covered | D4: guest-babysitting; breakfast child price in breakfast FAQs
A5: G04 | B5: Breakfast for children under 6 | C5: Still open
A6: G05 | B6: Air conditioning / heating | C6: Covered | D6: guest-air-conditioning
A7: G06 | B7: Smoking policy | C7: Covered | D7: guest-nonsmoking
A8: G07 | B8: Nearest U-Bahn / public transport | C8: Still open | D8: Existing airport answer uses train + bus only
A9: G08 | B9: Getting here from Hauptbahnhof / by train | C9: Still open
A10: G09 | B10: Luggage storage after check-out | C10: Covered | D10: guest-luggage
A11: G10 | B11: Early check-in | C11: Covered | D11: check-in-time (€30 from 06:00)
A12: G11 | B12: Laundry turnaround and prices | C12: Still open | D12: F24 (net new) has no turnaround/prices
A13: G12 | B13: Breakfast included in rate? Dietary options | C13: Partly covered | D13: breakfast-times mentions vegan options
A14: G13 | B14: EV charging | C14: Covered | D14: guest-ev-charging (but see C5)
A15: G14 | B15: In-room safe | C15: Covered | D15: guest-safe
A16: G15 | B16: Printing: cost and who | C16: Still open | D16: Possibly guest-business-center
A17: G16 | B17: Pets other than dogs | C17: Still open | D17: See C9
A18: G17 | B18: Lütze opening hours | C18: Covered – needs fixing | D18: guest-lutze-hours is typed text; should be computed
