Workbook

Sheet README
A1: Hotel Berlin, Berlin – FAQ triage workbook
A2: Built from the DialogShift chatbot export (42 rows). Every answer below is a DRAFT: the chatbot's answers were never signed off, and several contradict each other or the project.
A4: Sheets
A5: FAQs – the merged, rewritten set (EN + DE). Edit blue cells (topic, audience, priority, pins).
A6: Taxonomy – the topic list. FAQs belong to one topic plus an optional second.
A7: Tokens – every price, time, phone number and email is a {{token}} resolved from one source of truth, never typed into answer text.
A8: Routes – each page template, the topics it pulls, and its cap. Matched / Pinned / Shown / Trimmed are live.
A9: Placement – live matrix: which FAQ appears on which route. Change a topic, audience or pin and it updates.
A10: Gaps – FAQs the site needs that the chatbot export doesn't contain.
A11: Contact routing – the 'which email do I use' answers, to become a contact block rather than FAQs.
A12: Source map – all 42 original rows and where each one went.
A14: Rules the placement matrix applies
... A19: Status summary
A20: FAQs in total | B20: =COUNTA(FAQs!A2:A39) -> 38
A21: Ready | B21: =COUNTIF(FAQs!L2:L39,"Ready") -> 16
A22: Needs confirm | B22: =COUNTIF(FAQs!L2:L39,"Needs confirm") -> 16
A23: HOLD (do not publish) | B23: =COUNTIF(FAQs!L2:L39,"HOLD") -> 6
A24: Tokens in total | B24: =COUNTA(Tokens!A2:A30) -> 29
A25: Tokens needing a decision (Needs confirm + HOLD) | B25: =COUNTIF(Tokens!E2:E30,"Needs confirm")+COUNTIF(Tokens!E2:E30,"HOLD") -> 14
A26: Gaps to write | B26: =COUNTA(Gaps!A2:A18) -> 17
A27: Routes that over-fill their cap | B27: =COUNTIF(Routes!L2:L19,">0") -> 4
A28: Routes with no FAQ at all | B28: =COUNTIF(Routes!I2:I19,0) -> 1
A29: FAQs that appear on no route | B29: =COUNTIF(Placement!U2:U39,0) -> 0

Sheet FAQs
A1: ID | B1: Source rows (original sheet) | C1: Topic | D1: Topic 2 | E1: Audience | F1: Priority (1 = top) | G1: Pin to routes | H1: Question (EN) | I1: Answer (EN) | J1: Question (DE) | K1: Answer (DE) | L1: Status | M1: Flags / open questions
A2: F01 | B2: 10 | C2: checkin-checkout | E2: both | F2: 1 | H2: What time can I check in, and what if I arrive late? | I2: Check-in starts at {{checkinTime}}. Reception is staffed 24 hours a day, so you can arrive at any hour, even if you're held up on the road. If you expect to arrive after 18:00, it helps if you let us know in advance, but you don't have to. | J2: Ab wann kann ich einchecken, und was ist, wenn ich spät ankomme? | K2: Der Check-in beginnt um {{checkinTime}} Uhr. Die Rezeption ist rund um die Uhr besetzt, du kannst also jederzeit anreisen, auch wenn du im Stau steckst. Wenn du nach 18:00 Uhr ankommst, sag uns gern vorher Bescheid – das hilft uns, ist aber nicht nötig. | L2: Needs confirm | M2: Chatbot never states the standard check-in time. 15:00 comes from the original Cursor brief stub (checkinTime) – hotel to confirm.
A3: F02 | B3: 16 | C3: checkin-checkout | E3: both | F3: 2 | H3: Can I check in online? | I3: Yes. A few days before you arrive we'll email you an invitation to check in online, from home or on the move. Once that's done, collect your room key at the self-check-in desk in the lobby. If anything goes wrong, reach the team by chat or call {{phoneReception}} at any time. | J3: Kann ich online einchecken? | K3: Ja. Ein paar Tage vor deiner Anreise schicken wir dir eine E-Mail mit der Einladung zum Online-Check-in – von zu Hause oder unterwegs. Danach holst du deinen Zimmerschlüssel am Self-Check-in-Desk in der Lobby ab. Wenn etwas nicht klappt, erreichst du das Team jederzeit per Chat oder unter {{phoneReception}}. | L3: Needs confirm | M3: Phone number conflict – see Tokens. Confirm the chat channel is live on the new site.
A4: F03 | B4: 25 | C4: checkin-checkout | E4: both | F4: 2 | H4: Can I leave my luggage before check-in? | I4: Yes, you're welcome to leave your luggage with us before you check in. Just speak to a member of staff in the lobby. | J4: Kann ich mein Gepäck vor dem Check-in abgeben? | K4: Ja, dein Gepäck kannst du gern vor dem Check-in bei uns lassen. Sprich dafür einfach unser Team in der Lobby an. | L4: Ready | M4: Storage AFTER check-out is not covered anywhere – see Gaps G09.
A5: F04 | B5: 7 | C5: checkin-checkout | E5: both | F5: 1 | G5: policy-fees | H5: What time is check-out, and can I stay longer? | I5: Check-out is until {{checkoutTime}} on the day you leave. If you'd like to stay longer, please speak to reception in advance. Late check-out until {{lateCheckoutTime}} is available for {{lateCheckoutFee}}, subject to availability. | J5: Wann ist der Check-out, und kann ich länger bleiben? | K5: Der Check-out ist am Abreisetag bis {{checkoutTime}} Uhr möglich. Wenn du länger bleiben möchtest, sprich bitte vorab mit der Rezeption. Ein später Check-out bis {{lateCheckoutTime}} Uhr ist je nach Verfügbarkeit für {{lateCheckoutFee}} möglich. | L5: Ready | M5: Check-out 12:00 matches the brief stub.
A6: F05 | B6: 27 | C6: checkin-checkout | E6: guest | F6: 3 | H6: Do I need to leave my key in the room at check-out? | I6: No. Check out at one of the check-out terminals in the lobby, or check out online and drop your key in the key box. If you need help, ask reception. | J6: Muss ich beim Check-out den Schlüssel im Zimmer lassen? | K6: Nein. Du kannst an den Check-out-Terminals in der Lobby auschecken oder online auschecken und deinen Schlüssel in die Rückgabebox werfen. Bei Fragen hilft dir die Rezeption gern. | L6: Ready
A7: F06 | B7: 11, 12 | C7: parking | D7: getting-here | E7: both | F7: 1 | G7: policy-fees, meetings | H7: Can I reserve parking, and how much does it cost? | I7: You can't reserve a space in advance, and you don't need to: there are {{parkingSpaces}} spaces, outdoors and in an underground garage (maximum vehicle height {{parkingMaxHeight}}). Parking costs {{parkingHourly}} per hour, up to a maximum of {{parkingDaily}} per 24-hour period. A parking day is counted in 24-hour blocks, so you pay the hourly rate until you reach the daily maximum. | J7: Kann ich einen Parkplatz reservieren, und was kostet das Parken? | K7: Eine Reservierung ist nicht möglich und auch nicht nötig: Es gibt {{parkingSpaces}} Stellplätze im Freien und in der Tiefgarage (maximale Fahrzeughöhe {{parkingMaxHeight}}). Parken kostet {{parkingHourly}} pro Stunde, höchstens {{parkingDaily}} pro 24-Stunden-Zeitraum. Ein Parktag wird in 24-Stunden-Blöcken gerechnet: Bis zum Tageshöchstsatz zahlst du den Stundentarif. | L7: Ready | M7: Merged rows 11 + 12. Row 11 said 'over 200 spaces', row 12 said 208 – token uses 208. Confirm still current. Prices live in a token, not in text.
A8: F07 | B8: 22 | C8: getting-here | E8: both | F8: 1 | G8: home, meetings | H8: Do you offer an airport transfer, and how do I get to the hotel from the airport? | I8: We don't run our own airport shuttle, but public transport works well. From the airport, take the RE20 or FEX train to Südkreuz, then bus 106 to Lützowplatz, which stops right outside our door. Alternatively, take bus M46 to Schillstraße. | J8: Gibt es einen Flughafentransfer, und wie komme ich vom Flughafen zum Hotel? | K8: Einen eigenen Shuttle vom Flughafen haben wir nicht, mit den Öffentlichen kommst du aber gut zu uns. Vom Flughafen nimmst du den RE20 oder FEX bis Südkreuz und dann den Bus 106 bis Lützowplatz – die Haltestelle liegt direkt vor unserer Tür. Alternativ fährt der Bus M46 bis Schillstraße. | L8: Needs confirm | M8: VERIFY the route against current BVG/VBB data (RE20/FEX to Südkreuz from BER). Chatbot emojis removed. Related: Gaps G07/G08.
A9: F08 | B9: 4 | C9: breakfast | D9: dining | E9: both | F9: 1 | H9: When is breakfast served? | I9: Breakfast is served Monday to Friday from {{breakfastWeekday}}, and at weekends and on public holidays from {{breakfastWeekend}}. | J9: Wann gibt es Frühstück? | K9: Frühstück gibt es montags bis freitags von {{breakfastWeekday}} Uhr, am Wochenende und an Feiertagen von {{breakfastWeekend}} Uhr. | L9: Ready
A10: F09 | B10: 6 | C10: breakfast | E10: guest | F10: 2 | H10: Where is the breakfast restaurant? | I10: The breakfast restaurant is at the end of the lobby hall. | J10: Wo finde ich das Frühstücksrestaurant? | K10: Das Frühstücksrestaurant liegt am Ende der Lobbyhalle. | L10: Ready | M10: Dropped the 'follow the aroma of fresh bread rolls' chatbot line – add back if you want that voice.
A11: F10 | B11: 14 | C11: breakfast | E11: both | F11: 2 | G11: policy-fees | H11: Can I book breakfast after I've booked my room, and what does it cost? | I11: Yes. If you didn't add breakfast when you booked, you can add it later for {{breakfastPrice}} per person. Children aged {{breakfastChildMinAge}} and over pay {{breakfastPriceChild}}. | J11: Kann ich Frühstück nachbuchen, und was kostet es? | K11: Ja. Wenn du bei der Buchung kein Frühstück gewählt hast, kannst du es später für {{breakfastPrice}} pro Person dazubuchen. Kinder ab {{breakfastChildMinAge}} Jahren zahlen {{breakfastPriceChild}}. | L11: Ready | M11: Children under 6 not covered – Gaps G04.
A12: F11 | B12: 5 | C12: dining | D12: in-room | E12: both | F12: 2 | H12: Do you have room service? | I12: There's no room service, but the team is happy to recommend good delivery services in Berlin – just ask at reception. You can also pick up your breakfast or dinner from the restaurant and enjoy it in your room. | J12: Gibt es Zimmerservice? | K12: Einen Zimmerservice gibt es nicht. Die Rezeption empfiehlt dir aber gern gute Lieferdienste in Berlin. Du kannst dir auch Frühstück oder Abendessen im Restaurant abholen und auf dem Zimmer essen. | L12: Needs confirm | M12: Confirm that taking breakfast/dinner to the room is really allowed (chatbot claim).
A13: F12 | B13: 15 | C13: wifi | D13: in-room | E13: both | F13: 1 | H13: How do I connect to the WiFi? | I13: WiFi is free throughout the hotel. Connect to the network {{wifiSsid}}; the login page should open automatically. Accept the terms and conditions and you're online. | J13: Wie verbinde ich mich mit dem WLAN? | K13: Im ganzen Haus gibt es kostenloses WLAN. Verbinde dich mit dem Netzwerk {{wifiSsid}}; die Anmeldeseite öffnet sich automatisch. Akzeptiere die Nutzungsbedingungen, und du bist online. | L13: HOLD | M13: Standing instruction: do not seed WiFi details as fact until the hotel confirms (launch checklist 3.12 / D3). Removed 'high-speed' – no speed is claimed anywhere else.
A14: F13 | B14: 17 | C14: pets | E14: both | F14: 1 | G14: policy-fees | H14: Can I bring my dog? | I14: Yes, dogs are welcome. There's a charge of {{petFee}} per night. Please tell us in advance that you're bringing your dog so we can prepare. Dogs are also welcome at breakfast. Questions? Email {{emailInfo}} or call {{phoneMain}}. | J14: Kann ich meinen Hund mitbringen? | K14: Ja, Hunde sind bei uns willkommen. Wir berechnen {{petFee}} pro Nacht. Gib uns bitte vorab Bescheid, dass du deinen Hund mitbringst, damit wir alles vorbereiten können. Dein Hund darf auch mit zum Frühstück. Fragen? Schreib an {{emailInfo}} oder ruf an unter {{phoneMain}}. | L14: Needs confirm | M14: Original said 'pets such as dogs' – are other pets allowed? (Gaps G16). Phone conflict.
A15: F14 | B15: 18 | C15: rooms | E15: prospect | F15: 1 | H15: Can I request a quiet room? | I15: Every room category has rooms facing the street and rooms facing the courtyard. If you're sensitive to noise, mention it when you book and reception will do its best to give you a quieter room. | J15: Kann ich ein ruhiges Zimmer bekommen? | K15: In jeder Zimmerkategorie gibt es Zimmer zur Straße und zum Innenhof. Wenn du lärmempfindlich bist, gib das bitte bei der Buchung an – die Rezeption versucht dann, dir ein ruhigeres Zimmer zuzuweisen. | L15: Ready | M15: Dropped 'situated in the centre of the capital' (imprecise).
A16: F15 | B16: 38 | C16: rooms | E16: prospect | F16: 2 | H16: Do any rooms have a balcony? | I16: Some Premium rooms have a very small balcony. It has no seating, and smoking isn't permitted there. If a balcony matters to you, mention it when you book and we'll try to accommodate you, subject to availability. | J16: Gibt es Zimmer mit Balkon? | K16: Einige Premium-Zimmer haben einen sehr kleinen Balkon. Er hat keine Sitzmöbel, und Rauchen ist dort nicht erlaubt. Wenn dir ein Balkon wichtig ist, gib das bitte bei der Buchung an; wir versuchen dann, ihn je nach Verfügbarkeit zu berücksichtigen. | L16: Ready | M16: Good candidate to pin to specific room-detail pages via pinnedEntities (only rooms that actually have balconies).
A17: F16 | B17: 35 | C17: rooms | E17: prospect | F17: 2 | H17: Which are the largest rooms? | I17: The largest is Studio 45 at {{roomLargestSize}}, with its own sauna, a large bath, a lounge, a DJ deck and vinyl records. Next come the Premium Family Rooms (from {{roomFamilySize}}), and the Premium Rooms are also spacious at {{roomPremiumSize}}. | J17: Welche Zimmer sind die größten? | K17: Das größte Zimmer ist das Studio 45 mit {{roomLargestSize}}, mit eigener Sauna, großer Badewanne, Lounge, DJ-Pult und Vinylplatten. Danach kommen die Premium Family Rooms (ab {{roomFamilySize}}); auch die Premium-Zimmer sind mit {{roomPremiumSize}} sehr geräumig. | L17: Needs confirm | M17: Check against rooms.floorSizeM2 – ideally the tokens read from the rooms collection. 'Studio 45' at 95 m² – confirm the name/size pairing.
A18: F17 | B18: 32 | C18: rooms | D18: in-room | E18: guest | F18: 3 | H18: How do I find my room? | I18: Check your room number. Three-digit numbers (for example 315) are in the premium wing on the 3rd floor – take the lifts at the end of the lobby hall. For four-digit numbers (for example 1315), take the lifts in the lobby hall next to the kiosks. [CONFIRM: floor for four-digit rooms] | J18: Wie finde ich mein Zimmer? | K18: Schau auf deine Zimmernummer. Dreistellige Nummern (z. B. 315) liegen im Premium-Flügel im 3. Stock – nimm die Aufzüge am Ende der Lobbyhalle. Bei vierstelligen Nummern (z. B. 1315) nimmst du die Aufzüge in der Lobbyhalle neben den Kiosken. [BESTÄTIGEN: Etage der vierstelligen Zimmer] | L18: HOLD | M18: Original says BOTH 315 and 1315 are on the 3rd floor – almost certainly wrong. Also the original had unbalanced brackets.
A19: F18 | B19: 23 | C19: in-room | E19: guest | F19: 3 | H19: Do I need my key card to use the lifts? | I19: Yes, you need your key card to use the lifts. | J19: Brauche ich meine Schlüsselkarte für den Aufzug? | K19: Ja, für die Aufzüge brauchst du deine Schlüsselkarte. | L19: Ready
A20: F19 | B20: 31 | C20: in-room | E20: both | F20: 2 | H20: Is there a Nespresso machine in the room? | I20: Yes, your room has a Nespresso machine for your use. [CONFIRM: capsules included? complimentary or charged?] | J20: Gibt es eine Nespresso-Maschine im Zimmer? | K20: Ja, in deinem Zimmer steht eine Nespresso-Maschine zur Verfügung. [BESTÄTIGEN: Kapseln inklusive? Kostenlos oder kostenpflichtig?] | L20: HOLD | M20: Chatbot said capsules are 'from Rezemo' – looks like a typo/hallucination; not repeated. Need the real answer.
A21: F20 | B21: 33 | C21: in-room | D21: sustainability | E21: both | F21: 2 | G21: sustainability | H21: Is my room cleaned every day? | I21: We clean your room every second day. If you'd rather skip a cleaning, you can become a Green Hero and opt out. | J21: Wird mein Zimmer täglich gereinigt? | K21: Wir reinigen dein Zimmer jeden zweiten Tag. Wenn du darauf verzichten möchtest, werde Green Hero und überspringe die Reinigung. | L21: Needs confirm | M21: Explain how the Green Hero opt-out works (sign at reception? door hanger? any reward?) and link to the sustainability page.
A22: F21 | B22: 42 | C22: in-room | E22: both | F22: 2 | H22: Can I connect my own streaming stick (e.g. Amazon Fire TV) to the TV? | I22: Unfortunately not – the TV's HDMI ports are locked for other devices. Ask reception about your options; some rooms may have a streaming platform built in. | J22: Kann ich meinen eigenen Streaming-Stick (z. B. Amazon Fire TV) am Fernseher anschließen? | K22: Leider nicht – die HDMI-Anschlüsse sind für andere Geräte gesperrt. Frag bitte an der Rezeption nach Alternativen; eventuell gibt es Zimmer mit integrierter Streaming-Plattform. | L22: Needs confirm | M22: 'Maybe rooms with integrated streaming' is vague – which rooms? Casting (Chromecast/AirPlay) not mentioned.
A23: F22 | B23: 43 | C23: services | D23: in-room | E23: guest | F23: 3 | H23: Where can I get a power adapter? | I23: The Wundermart shop in our lobby has what you need. [CONFIRM: adapters stocked? loan at reception?] | J23: Wo bekomme ich einen Steckdosenadapter? | K23: In unserer Lobby findest du den Wundermart-Shop – dort gibt es, was du brauchst. [BESTÄTIGEN: Adapter im Sortiment? Verleih an der Rezeption?] | L23: Needs confirm | M23: Chatbot said 'anything you need' without naming adapters.
A24: F23 | B24: 3 | C24: services | D24: in-room | E24: guest | F24: 3 | H24: Can I borrow an iron or an ironing board? | I24: Yes – call reception on {{phoneReception}} and the team will bring an iron to your room. [CONFIRM: ironing board available?] | J24: Kann ich ein Bügeleisen oder ein Bügelbrett leihen? | K24: Ja – ruf die Rezeption unter {{phoneReception}} an, dann bringt dir das Team ein Bügeleisen aufs Zimmer. [BESTÄTIGEN: Bügelbrett verfügbar?] | L24: Needs confirm | M24: Guest asked for an ironing board; the chatbot only answered about an iron.
A25: F24 | B25: 8, 9 | C25: services | E25: both | F25: 2 | H25: Do you offer a laundry service? | I25: Yes. We pick up your laundry from your room and have it cleaned by an external laundry – just let the team know. There are no coin-operated or self-service laundry facilities in the hotel. | J25: Gibt es einen Wäscheservice? | K25: Ja. Wir holen deine Wäsche auf dem Zimmer ab und lassen sie extern reinigen – sag dem Team einfach Bescheid. Einen Waschsalon oder Self-Service-Waschmaschinen gibt es im Haus nicht. | L25: Needs confirm | M25: Merged rows 8 + 9. No turnaround time or prices anywhere – Gaps G11.
A26: F25 | B26: 39 | C26: services | E26: guest | F26: 3 | H26: Can you print a document for me? | I26: Yes. Email the attachment to {{emailInfo}} and the reception team will print it for you. | J26: Könnt ihr ein Dokument für mich ausdrucken? | K26: Ja. Schick den Anhang per E-Mail an {{emailInfo}}, die Rezeption druckt ihn für dich aus. | L26: Needs confirm | M26: Any charge? Guests only? Gaps G15.
A27: F26 | B27: 20 | C27: wellness | E27: both | F27: 1 | G27: here | H27: What are the sauna opening hours? | I27: Our complimentary sauna area has a Finnish sauna and a sanarium. It's open daily {{saunaHours}}, except June to August, when it's available on request. Please let reception know at least {{saunaNotice}} before your visit so it can be prepared. | J27: Wann ist die Sauna geöffnet? | K27: In unserem kostenlosen Saunabereich findest du eine finnische Sauna und ein Sanarium. Geöffnet ist täglich {{saunaHours}} Uhr, außer von Juni bis August – dann auf Anfrage. Sag bitte mindestens {{saunaNotice}} vor deinem Besuch an der Rezeption Bescheid, damit wir alles vorbereiten können. | L27: HOLD | M27: Launch checklist 3.13: two published sauna schedules conflict. Don't publish hours until the hotel picks one.
A28: F27 | B28: 21 | C28: wellness | E28: both | F28: 3 | H28: Is the sauna clothing-free? | I28: In Germany it's common to use the sauna without swimwear, usually wrapped in a towel. In our hotel it isn't required – if you feel more comfortable covered up, that's absolutely fine. | J28: Ist die Sauna textilfrei? | K28: In Deutschland ist es üblich, ohne Badebekleidung in die Sauna zu gehen, meist nur mit einem Handtuch. Bei uns im Hotel ist das keine Pflicht – wenn du dich bekleidet wohler fühlst, ist das völlig in Ordnung. | L28: Ready | M28: Chatbot wrote 'textile clothing'; softened to 'swimwear'.
A29: F28 | B29: 30 | C29: wellness | E29: both | F29: 2 | G29: here | H29: Who can use the gym? | I29: The fitness area is free for all hotel guests and open around the clock, 24/7. It is for hotel guests only. | J29: Wer darf den Fitnessraum nutzen? | K29: Der Fitnessbereich ist für alle Hotelgäste kostenlos und rund um die Uhr geöffnet. Die Nutzung ist Hotelgästen vorbehalten. | L29: Needs confirm | M29: Original contained 'no age restriction at the Quellen' – nonsense artefact, removed. Is there actually an age restriction? Open.
A30: F29 | B30: 24 | C30: activities | E30: both | F30: 2 | H30: Is there still a fingerboard park? | I30: Yes, the fingerboard park is still there. [ADD: where to find it, opening times] | J30: Gibt es den Fingerboard-Park noch? | K30: Ja, den Fingerboard-Park gibt es noch. [ERGÄNZEN: Ort und Zeiten] | L30: HOLD | M30: Launch checklist 3.15: location, photos and hours still outstanding from the hotel.
A31: F30 | B31: 34 | C31: bikes | E31: both | F31: 2 | H31: Can I store my own bike at the hotel? | I31: Yes, you're welcome to bring your own bicycle. You can store it safely in a dedicated garage at the hotel. | J31: Kann ich mein eigenes Fahrrad im Hotel unterstellen? | K31: Ja, du kannst dein Fahrrad gern mitbringen und sicher in unserer Fahrradgarage abstellen. | L31: Ready
A32: F31 | B32: 44 | C32: bikes | D32: getting-here | E32: both | F32: 2 | H32: Can I rent a bike? | I32: Yes, there's a bike hire station right at the hotel. Scan the QR code at the station, download the app, and you're ready to ride. | J32: Kann ich ein Fahrrad leihen? | K32: Ja, direkt im Hotel gibt es eine Leihstation. Scanne dort den QR-Code, lade die App herunter, und es kann losgehen. | L32: Needs confirm | M32: Which provider/app, and what does it cost? Not stated.
A33: F32 | B33: 37 | C33: payment | E33: both | F33: 1 | H33: Can I pay without a credit card? | I33: Yes. We accept debit cards and contactless payments such as Apple Pay, Google Pay and Giropay. The hotel is entirely cashless, so we can't accept cash. | J33: Kann ich auch ohne Kreditkarte bezahlen? | K33: Ja. Wir akzeptieren Debitkarten und kontaktlose Zahlungen wie Apple Pay, Google Pay und Giropay. Das Hotel ist komplett bargeldlos, Barzahlung ist daher nicht möglich. | L33: Needs confirm | M33: VERIFY Giropay is still a live payment method. 'Entirely cashless' is a policy statement – hotel to confirm wording (feeds /policies/payment).
A34: F33 | B34: 28 | C34: loyalty | E34: prospect | F34: 2 | H34: Do you have a loyalty programme? | I34: Yes, you can take part in Radisson Rewards, which is open to new and returning guests. Members can earn points towards free nights, get member rates and discounts on food and drinks, and enjoy priority check-in and check-out. See the programme terms for current benefits. | J34: Gibt es ein Bonusprogramm? | K34: Ja, du kannst bei uns an Radisson Rewards teilnehmen – offen für neue und bestehende Mitglieder. Mitglieder sammeln Punkte für Freinächte, erhalten Mitgliedsraten und Rabatte auf Speisen und Getränke und profitieren von bevorzugtem Check-in und Check-out. Aktuelle Vorteile findest du in den Programmbedingungen. | L34: Needs confirm | M34: Removed 'save up to 15%' and 'easier premium status' – third-party programme claims that go stale. Confirm programme name and link target.
A35: F34 | B35: 29 | C35: lost-property | D35: contact | E35: guest | F35: 2 | H35: I lost something at the hotel. What should I do? | I35: Our Guest Care Center keeps a record of all found items. Register your lost item using our online form ({{lostPropertyUrl}}) and we'll get back to you. | J35: Ich habe etwas im Hotel verloren – was kann ich tun? | K35: Unser Guest Care Center führt eine Liste aller gefundenen Gegenstände. Melde deinen Verlust über unser Online-Formular ({{lostPropertyUrl}}), wir melden uns bei dir. | L35: Ready | M35: Original answer lost its first letter ('f you have lost…'). Emoji removed. Confirm the form URL.
A36: F35 | B36: 36 | C36: meetings | E36: prospect | F36: 1 | H36: How do I book a meeting room? | I36: Send us an enquiry through our meeting request form, or email our conference team at {{emailConference}}. | J36: Wie buche ich einen Tagungsraum? | K36: Nutze unser Anfrageformular für Tagungen oder schreib an unser Conference-Team: {{emailConference}}. | L36: Ready | M36: Chatbot only gave the email; form reference added from the Meetings brief (/meetings/request).
A37: F36 | B37: 19, 26 | C37: contact | E37: both | F37: 1 | H37: How can I contact the hotel? | I37: Phone: {{phoneMain}}. Email: {{emailInfo}}. For room and booking enquiries: {{emailReservations}}. Address: {{hotelAddress}}. | J37: Wie kann ich das Hotel kontaktieren? | K37: Telefon: {{phoneMain}}. E-Mail: {{emailInfo}}. Für Zimmer- und Buchungsanfragen: {{emailReservations}}. Adresse: {{hotelAddress}}. | L37: HOLD | M37: Merged rows 19 + 26. Three different phone numbers in the sheet – see Tokens. Should really be a contact block, not an accordion item.
A38: F37 | B38: 41 | C38: payment | D38: contact | E38: both | F38: 3 | H38: How do I change a prepayment invoice? | I38: Email {{emailInfo}} with the invoice number, the new billing address and the email address the amended invoice should be sent to. | J38: Wie lasse ich eine Vorauszahlungsrechnung ändern? | K38: Schreib an {{emailInfo}} und gib die Rechnungsnummer, die neue Rechnungsadresse und die E-Mail-Adresse an, an die die geänderte Rechnung gehen soll. | L38: Ready | M38: Only relevant to people with an existing booking – low priority.
A39: F38 | B39: 40 | C39: sustainability | D39: contact | E39: both | F39: 2 | H39: Who is the contact for sustainability? | I39: Our Sustainability Manager is happy to answer your questions: {{emailSustainability}}. | J39: Wer ist Ansprechperson für Nachhaltigkeit? | K39: Unser Nachhaltigkeitsmanagement beantwortet deine Fragen gern: {{emailSustainability}}. | L39: Ready | M39: Better as a contact line on the sustainability page; kept here so the topic has an entry.

Sheet Taxonomy
A1: Topic slug | B1: Label (EN) | C1: Label (DE) | D1: Covers | E1: FAQs (primary + secondary)
A2: checkin-checkout | B2: Check-in & check-out | C2: Check-in & Check-out | D2: Times, online check-in, luggage, late check-out | E2: =COUNTIF(FAQs!$C$2:$C$39,A2)+COUNTIF(FAQs!$D$2:$D$39,A2) -> 5
A3: getting-here | B3: Getting here | C3: Anreise | D3: Airport, trains, public transport | E3: =COUNTIF(FAQs!$C$2:$C$39,A3)+COUNTIF(FAQs!$D$2:$D$39,A3) -> 3
A4: parking | B4: Parking | C4: Parken | D4: Spaces, prices, height limits | E4: =COUNTIF(FAQs!$C$2:$C$39,A4)+COUNTIF(FAQs!$D$2:$D$39,A4) -> 1
A5: breakfast | B5: Breakfast | C5: Frühstück | D5: Times, location, price | E5: =COUNTIF(FAQs!$C$2:$C$39,A5)+COUNTIF(FAQs!$D$2:$D$39,A5) -> 3
A6: dining | B6: Eating & drinking | C6: Essen & Trinken | D6: Restaurant, bar, room service | E6: =COUNTIF(FAQs!$C$2:$C$39,A6)+COUNTIF(FAQs!$D$2:$D$39,A6) -> 2
A7: rooms | B7: Rooms | C7: Zimmer | D7: Room types, views, balconies, sizes | E7: =COUNTIF(FAQs!$C$2:$C$39,A7)+COUNTIF(FAQs!$D$2:$D$39,A7) -> 4
A8: in-room | B8: In your room | C8: Im Zimmer | D8: Equipment and housekeeping | E8: =COUNTIF(FAQs!$C$2:$C$39,A8)+COUNTIF(FAQs!$D$2:$D$39,A8) -> 9
A9: wifi | B9: WiFi | C9: WLAN | D9: Connecting and terms | E9: =COUNTIF(FAQs!$C$2:$C$39,A9)+COUNTIF(FAQs!$D$2:$D$39,A9) -> 1
A10: wellness | B10: Sauna & fitness | C10: Sauna & Fitness | D10: Sauna, gym | E10: =COUNTIF(FAQs!$C$2:$C$39,A10)+COUNTIF(FAQs!$D$2:$D$39,A10) -> 3
A11: activities | B11: Activities | C11: Freizeit | D11: Fingerboard park and other on-site activities | E11: =COUNTIF(FAQs!$C$2:$C$39,A11)+COUNTIF(FAQs!$D$2:$D$39,A11) -> 1
A12: services | B12: Services | C12: Services | D12: Laundry, printing, iron, adapters | E12: =COUNTIF(FAQs!$C$2:$C$39,A12)+COUNTIF(FAQs!$D$2:$D$39,A12) -> 4
A13: bikes | B13: Bikes | C13: Fahrrad | D13: Storage and rental | E13: =COUNTIF(FAQs!$C$2:$C$39,A13)+COUNTIF(FAQs!$D$2:$D$39,A13) -> 2
... A21: cancellation | B21: Cancellation | C21: Stornierung | D21: No FAQs yet – see Gaps | E21: =COUNTIF(FAQs!$C$2:$C$39,A21)+COUNTIF(FAQs!$D$2:$D$39,A21) -> 0

Sheet Tokens
A1: Token | B1: Value (EN) | C1: Value (DE) | D1: Source of truth (proposed) | E1: Status | F1: Note | G1: Used in # EN answers
A2: {{checkinTime}} | B2: 15:00 | C2: 15:00 | D2: hotel global → checkinTime | E2: Needs confirm | F2: From brief stub only; chatbot never says it. | G2: =COUNTIF(FAQs!$I$2:$I$39,"*"&A2&"*") -> 1
A3: {{checkoutTime}} | B3: 12:00 | C3: 12:00 | D3: hotel global → checkoutTime | E3: Ready | F3: Matches chatbot and brief stub. | G3: =COUNTIF(FAQs!$I$2:$I$39,"*"&A3&"*") -> 1
A4: {{lateCheckoutTime}} | B4: 15:00 | C4: 15:00 | D4: hotel global → lateCheckout.until | E4: Ready | G4: =COUNTIF(FAQs!$I$2:$I$39,"*"&A4&"*") -> 1
A5: {{lateCheckoutFee}} | B5: €30 | C5: 30 € | D5: hotel global → lateCheckout.fee | E5: Ready | G5: =COUNTIF(FAQs!$I$2:$I$39,"*"&A5&"*") -> 1
A6: {{breakfastWeekday}} | B6: 6:30–10:00 | C6: 6:30–10:00 | D6: amenities / dining → breakfast.weekday | E6: Ready | G6: =COUNTIF(FAQs!$I$2:$I$39,"*"&A6&"*") -> 1
A7: {{breakfastWeekend}} | B7: 6:30–11:00 | C7: 6:30–11:00 | D7: amenities / dining → breakfast.weekend | E7: Ready | F7: Weekends and public holidays. | G7: =COUNTIF(FAQs!$I$2:$I$39,"*"&A7&"*") -> 1
A8: {{breakfastPrice}} | B8: €23.00 | C8: 23,00 € | D8: amenities / dining → breakfast.price | E8: Ready | G8: =COUNTIF(FAQs!$I$2:$I$39,"*"&A8&"*") -> 1
A9: {{breakfastPriceChild}} | B9: €11.50 | C9: 11,50 € | D9: amenities / dining → breakfast.priceChild | E9: Ready | G9: =COUNTIF(FAQs!$I$2:$I$39,"*"&A9&"*") -> 1
A10: {{breakfastChildMinAge}} | B10: 6 | C10: 6 | D10: amenities / dining → breakfast.childMinAge | E10: Ready | F10: Under-6 policy unknown. | G10: =COUNTIF(FAQs!$I$2:$I$39,"*"&A10&"*") -> 1
A11: {{parkingSpaces}} | B11: 208 | C11: 208 | D11: amenities → parking.spaces | E11: Needs confirm | F11: Chatbot also said 'over 200'. | G11: =COUNTIF(FAQs!$I$2:$I$39,"*"&A11&"*") -> 1
A12: {{parkingHourly}} | B12: €4 | C12: 4 € | D12: amenities → parking.hourly | E12: Ready | G12: =COUNTIF(FAQs!$I$2:$I$39,"*"&A12&"*") -> 1
A13: {{parkingDaily}} | B13: €25 | C13: 25 € | D13: amenities → parking.dailyMax | E13: Ready | G13: =COUNTIF(FAQs!$I$2:$I$39,"*"&A13&"*") -> 1
A14: {{parkingMaxHeight}} | B14: 1.80 m | C14: 1,80 m | D14: amenities → parking.maxHeight | E14: Ready | G14: =COUNTIF(FAQs!$I$2:$I$39,"*"&A14&"*") -> 1
A15: {{petFee}} | B15: €30 | C15: 30 € | D15: hotel global → policies.petFee | E15: Ready | F15: Per night. | G15: =COUNTIF(FAQs!$I$2:$I$39,"*"&A15&"*") -> 1
A16: {{wifiSsid}} | B16: HBB-Guestconnect | C16: HBB-Guestconnect | D16: hotel global → wifi.ssid | E16: HOLD | F16: Do not publish until confirmed (D3). Earlier docs mention a different SSID/password. | G16: =COUNTIF(FAQs!$I$2:$I$39,"*"&A16&"*") -> 1
A17: {{saunaHours}} | B17: 18:00–23:00 | C17: 18:00–23:00 | D17: amenities → sauna.hours | E17: HOLD | F17: Conflicts with a second published schedule (checklist 3.13). | G17: =COUNTIF(FAQs!$I$2:$I$39,"*"&A17&"*") -> 1
A18: {{saunaNotice}} | B18: 45 minutes | C18: 45 Minuten | D18: amenities → sauna.noticeMinutes | E18: Needs confirm | G18: =COUNTIF(FAQs!$I$2:$I$39,"*"&A18&"*") -> 1
A19: {{phoneMain}} | B19: +49 30 26050 | C19: +49 30 26050 | D19: hotel global → telephone | E19: HOLD | F19: Variants seen: +49 30 26050 / +493026050 / +49 30 2600 50 (brief stub). Pick one. | G19: =COUNTIF(FAQs!$I$2:$I$39,"*"&A19&"*") -> 2
A20: {{phoneReception}} | B20: +49 30 2605 3103 | C20: +49 30 2605 3103 | D20: hotel global → receptionPhone | E20: HOLD | F20: Appears in one chatbot answer only. | G20: =COUNTIF(FAQs!$I$2:$I$39,"*"&A20&"*") -> 2
A21: {{emailInfo}} | B21: info@hotel-berlin.de | C21: info@hotel-berlin.de | D21: hotel global → email | E21: Ready | G21: =COUNTIF(FAQs!$I$2:$I$39,"*"&A21&"*") -> 4
A22: {{emailReservations}} | B22: reservations@hotel-berlin.de | C22: reservations@hotel-berlin.de | D22: hotel global → emails.reservations | E22: Needs confirm | F22: Confirm mailbox exists/monitored. | G22: =COUNTIF(FAQs!$I$2:$I$39,"*"&A22&"*") -> 1
A23: {{emailConference}} | B23: conference@hotel-berlin.de | C23: conference@hotel-berlin.de | D23: meetings global → contactEmail | E23: Ready | F23: Same field the Meetings brief already uses. | G23: =COUNTIF(FAQs!$I$2:$I$39,"*"&A23&"*") -> 1
A24: {{emailSustainability}} | B24: sustainability@hotel-berlin.de | C24: sustainability@hotel-berlin.de | D24: hotel global → emails.sustainability | E24: Needs confirm | G24: =COUNTIF(FAQs!$I$2:$I$39,"*"&A24&"*") -> 1
A25: {{emailCareers}} | B25: karriere@hotel-berlin.de | C25: karriere@hotel-berlin.de | D25: hotel global → emails.careers | E25: Needs confirm | F25: Used on careers/contact routing, not in an FAQ. | G25: =COUNTIF(FAQs!$I$2:$I$39,"*"&A25&"*") -> 0
A26: {{hotelAddress}} | B26: Lützowplatz 17, 10785 Berlin | C26: Lützowplatz 17, 10785 Berlin | D26: hotel global → address | E26: Ready | G26: =COUNTIF(FAQs!$I$2:$I$39,"*"&A26&"*") -> 1
A27: {{lostPropertyUrl}} | B27: https://lost.faundit.com/hotel-berlin-berlin | C27: https://lost.faundit.com/hotel-berlin-berlin | D27: hotel global → lostPropertyUrl | E27: Needs confirm | F27: Third-party form – confirm still in use. | G27: =COUNTIF(FAQs!$I$2:$I$39,"*"&A27&"*") -> 1
A28: {{roomLargestSize}} | B28: 95 m² | C28: 95 m² | D28: rooms → studio-45.floorSizeM2 | E28: Needs confirm | F28: Should read from the rooms collection. | G28: =COUNTIF(FAQs!$I$2:$I$39,"*"&A28&"*") -> 1
A29: {{roomFamilySize}} | B29: 45 m² | C29: 45 m² | D29: rooms → premium-family.floorSizeM2 | E29: Needs confirm | F29: Chatbot said 'at least 45 m²'. | G29: =COUNTIF(FAQs!$I$2:$I$39,"*"&A29&"*") -> 1
A30: {{roomPremiumSize}} | B30: 36 m² | C30: 36 m² | D30: rooms → premium.floorSizeM2 | E30: Needs confirm | G30: =COUNTIF(FAQs!$I$2:$I$39,"*"&A30&"*") -> 1

Sheet Routes
A1: Route ID | B1: Path | C1: Audience | D1: Topic 1 | E1: Topic 2 | F1: Topic 3 | G1: Topic 4 | H1: Cap | I1: Matched | J1: Pinned | K1: Shown | L1: Trimmed | M1: Notes
A2: home | B2: / | C2: prospect | D2: checkin-checkout | E2: parking | F2: pets | G2: payment | H2: 6 | I2: =COUNTIF(Placement!C$2:C$39,"●") -> 9 | J2: =SUMPRODUCT(--ISNUMBER(SEARCH(","&A2&",",","&SUBSTITUTE(FAQs!$G$2:$G$39," ","")&","))) -> 1 | K2: =MAX(J2,MIN(H2,I2)) -> 6 | L2: =I2-K2 -> 3 | M2: Homepage FAQ strip. Priority-1 items win when over cap.
A3: rooms | B3: /rooms | C3: prospect | D3: rooms | E3: in-room | H3: 6 | I3: =COUNTIF(Placement!D$2:D$39,"●") -> 8 | J3: =SUMPRODUCT(--ISNUMBER(SEARCH(","&A3&",",","&SUBSTITUTE(FAQs!$G$2:$G$39," ","")&","))) -> 0 | K3: =MAX(J3,MIN(H3,I3)) -> 6 | L3: =I3-K3 -> 2
A4: room-detail | B4: /rooms/[slug] | C4: prospect | D4: rooms | E4: in-room | H4: 5 | I4: =COUNTIF(Placement!E$2:E$39,"●") -> 8 | J4: =SUMPRODUCT(--ISNUMBER(SEARCH(","&A4&",",","&SUBSTITUTE(FAQs!$G$2:$G$39," ","")&","))) -> 0 | K4: =MAX(J4,MIN(H4,I4)) -> 5 | L4: =I4-K4 -> 3 | M4: Entity pins (e.g. balcony FAQ only on rooms that have a balcony) are done with pinnedEntities, not shown here.
A5: meetings | B5: /meetings | C5: prospect | D5: meetings | E5: sustainability | H5: 5 | I5: =COUNTIF(Placement!F$2:F$39,"●") -> 5 | J5: =SUMPRODUCT(--ISNUMBER(SEARCH(","&A5&",",","&SUBSTITUTE(FAQs!$G$2:$G$39," ","")&","))) -> 2 | K5: =MAX(J5,MIN(H5,I5)) -> 5 | L5: =I5-K5 -> 0 | M5: Plus pinned parking + getting-here for event organisers.
A6: amenities | B6: /amenities (TBC) | C6: prospect | D6: wellness | E6: activities | F6: services | G6: bikes | H6: 8 | I6: =COUNTIF(Placement!G$2:G$39,"●") -> 7 | J6: =SUMPRODUCT(--ISNUMBER(SEARCH(","&A6&",",","&SUBSTITUTE(FAQs!$G$2:$G$39," ","")&","))) -> 0 | K6: =MAX(J6,MIN(H6,I6)) -> 7 | L6: =I6-K6 -> 0 | M6: Route name TBC against the Amenities brief.
A7: sustainability | B7: /sustainability | C7: prospect | D7: sustainability | H7: 5 | I7: =COUNTIF(Placement!H$2:H$39,"●") -> 2 | J7: =SUMPRODUCT(--ISNUMBER(SEARCH(","&A7&",",","&SUBSTITUTE(FAQs!$G$2:$G$39," ","")&","))) -> 1 | K7: =MAX(J7,MIN(H7,I7)) -> 2 | L7: =I7-K7 -> 0
A8: offers | B8: /offers | C8: prospect | D8: loyalty | H8: 5 | I8: =COUNTIF(Placement!I$2:I$39,"●") -> 1 | J8: =SUMPRODUCT(--ISNUMBER(SEARCH(","&A8&",",","&SUBSTITUTE(FAQs!$G$2:$G$39," ","")&","))) -> 0 | K8: =MAX(J8,MIN(H8,I8)) -> 1 | L8: =I8-K8 -> 0
A9: contact | B9: /contact | C9: prospect | D9: contact | E9: lost-property | H9: 8 | I9: =COUNTIF(Placement!J$2:J$39,"●") -> 3 | J9: =SUMPRODUCT(--ISNUMBER(SEARCH(","&A9&",",","&SUBSTITUTE(FAQs!$G$2:$G$39," ","")&","))) -> 0 | K9: =MAX(J9,MIN(H9,I9)) -> 3 | L9: =I9-K9 -> 0
A10: faq | B10: /faq (new) | C10: prospect | D10: ALL | H10: 99 | I10: =COUNTIF(Placement!K$2:K$39,"●") -> 30 | J10: =SUMPRODUCT(--ISNUMBER(SEARCH(","&A10&",",","&SUBSTITUTE(FAQs!$G$2:$G$39," ","")&","))) -> 0 | K10: =MAX(J10,MIN(H10,I10)) -> 30 | L10: =I10-K10 -> 0 | M10: Does not exist yet in the briefs – prospect-facing full list.
A11: here | B11: /here | C11: guest | D11: checkin-checkout | E11: wifi | F11: breakfast | G11: services | H11: 6 | I11: =COUNTIF(Placement!L$2:L$39,"●") -> 15 | J11: =SUMPRODUCT(--ISNUMBER(SEARCH(","&A11&",",","&SUBSTITUTE(FAQs!$G$2:$G$39," ","")&","))) -> 2 | K11: =MAX(J11,MIN(H11,I11)) -> 6 | L11: =I11-K11 -> 9 | M11: Guest hub – compact.
A12: here-dining | B12: /here/dining | C12: guest | D12: breakfast | E12: dining | H12: 6 | I12: =COUNTIF(Placement!M$2:M$39,"●") -> 4 | J12: =SUMPRODUCT(--ISNUMBER(SEARCH(","&A12&",",","&SUBSTITUTE(FAQs!$G$2:$G$39," ","")&","))) -> 0 | K12: =MAX(J12,MIN(H12,I12)) -> 4 | L12: =I12-K12 -> 0
A13: here-getting-around | B13: /here/getting-around | C13: guest | D13: getting-here | E13: bikes | F13: parking | H13: 6 | I13: =COUNTIF(Placement!N$2:N$39,"●") -> 4 | J13: =SUMPRODUCT(--ISNUMBER(SEARCH(","&A13&",",","&SUBSTITUTE(FAQs!$G$2:$G$39," ","")&","))) -> 0 | K13: =MAX(J13,MIN(H13,I13)) -> 4 | L13: =I13-K13 -> 0
A14: here-faq | B14: /here/faq | C14: guest | D14: ALL | H14: 99 | I14: =COUNTIF(Placement!O$2:O$39,"●") -> 33 | J14: =SUMPRODUCT(--ISNUMBER(SEARCH(","&A14&",",","&SUBSTITUTE(FAQs!$G$2:$G$39," ","")&","))) -> 0 | K14: =MAX(J14,MIN(H14,I14)) -> 33 | L14: =I14-K14 -> 0 | M14: Existing guest FAQ page.
A15: policy-checkin | B15: /policies/check-in | C15: prospect | D15: checkin-checkout | H15: 8 | I15: =COUNTIF(Placement!P$2:P$39,"●") -> 4 | J15: =SUMPRODUCT(--ISNUMBER(SEARCH(","&A15&",",","&SUBSTITUTE(FAQs!$G$2:$G$39," ","")&","))) -> 0 | K15: =MAX(J15,MIN(H15,I15)) -> 4 | L15: =I15-K15 -> 0
A16: policy-cancellation | B16: /policies/cancellation | C16: prospect | D16: cancellation | H16: 8 | I16: =COUNTIF(Placement!Q$2:Q$39,"●") -> 0 | J16: =SUMPRODUCT(--ISNUMBER(SEARCH(","&A16&",",","&SUBSTITUTE(FAQs!$G$2:$G$39," ","")&","))) -> 0 | K16: =MAX(J16,MIN(H16,I16)) -> 0 | L16: =I16-K16 -> 0 | M16: Empty until G01 is answered.
A17: policy-pets | B17: /policies/pets | C17: prospect | D17: pets | H17: 8 | I17: =COUNTIF(Placement!R$2:R$39,"●") -> 1 | J17: =SUMPRODUCT(--ISNUMBER(SEARCH(","&A17&",",","&SUBSTITUTE(FAQs!$G$2:$G$39," ","")&","))) -> 0 | K17: =MAX(J17,MIN(H17,I17)) -> 1 | L17: =I17-K17 -> 0
A18: policy-fees | B18: /policies/fees | C18: prospect | H18: 8 | I18: =COUNTIF(Placement!S$2:S$39,"●") -> 4 | J18: =SUMPRODUCT(--ISNUMBER(SEARCH(","&A18&",",","&SUBSTITUTE(FAQs!$G$2:$G$39," ","")&","))) -> 4 | K18: =MAX(J18,MIN(H18,I18)) -> 4 | L18: =I18-K18 -> 0 | M18: Pins only: late check-out, parking, breakfast price, dog fee.
A19: policy-payment | B19: /policies/payment | C19: prospect | D19: payment | H19: 8 | I19: =COUNTIF(Placement!T$2:T$39,"●") -> 2 | J19: =SUMPRODUCT(--ISNUMBER(SEARCH(","&A19&",",","&SUBSTITUTE(FAQs!$G$2:$G$39," ","")&","))) -> 0 | K19: =MAX(J19,MIN(H19,I19)) -> 2 | L19: =I19-K19 -> 0

Sheet Placement
A1: FAQ | B1: Question (EN) | C1: =Routes!A2 -> home | D1: =Routes!A3 -> rooms | E1: =Routes!A4 -> room-detail | F1: =Routes!A5 -> meetings | G1: =Routes!A6 -> amenities | H1: =Routes!A7 -> sustainability | I1: =Routes!A8 -> offers | J1: =Routes!A9 -> contact | K1: =Routes!A10 -> faq | L1: =Routes!A11 -> here | M1: =Routes!A12 -> here-dining | N1: =Routes!A13 -> here-getting-around | O1: =Routes!A14 -> here-faq | P1: =Routes!A15 -> policy-checkin | Q1: =Routes!A16 -> policy-cancellation | R1: =Routes!A17 -> policy-pets | S1: =Routes!A18 -> policy-fees | T1: =Routes!A19 -> policy-payment | U1: # routes
A2: =FAQs!A2 -> F01 | B2: =FAQs!H2 -> What time can I check in, and what if I arrive late? | C2: =IF(OR(ISNUMBER(SEARCH(","&C$1&",",","&SUBSTITUTE(FAQs!$G2," ","")&",")),AND(OR(FAQs!$E2="both",Routes!$C$2="both",FAQs!$E2=Routes!$C$2),OR(Routes!$D$2="ALL",COUNTIF(Routes!$D$2:$G$2,FAQs!$C2)>0,AND(FAQs!$D2<>"",COUNTIF(Routes!$D$2:$G$2,FAQs!$D2)>0)))),"●","") -> ● | D2: =IF(OR(ISNUMBER(SEARCH(","&D$1&",",","&SUBSTITUTE(FAQs!$G2," ","")&",")),AND(OR(FAQs!$E2="both",Routes!$C$3="both",FAQs!$E2=Routes!$C$3),OR(Routes!$D$3="ALL",COUNTIF(Routes!$D$3:$G$3,FAQs!$C2)>0,AND(FAQs!$D2<>"",COUNTIF(Routes!$D$3:$G$3,FAQs!$D2)>0)))),"●","") | E2: =IF(OR(ISNUMBER(SEARCH(","&E$1&",",","&SUBSTITUTE(FAQs!$G2," ","")&",")),AND(OR(FAQs!$E2="both",Routes!$C$4="both",FAQs!$E2=Routes!$C$4),OR(Routes!$D$4="ALL",COUNTIF(Routes!$D$4:$G$4,FAQs!$C2)>0,AND(FAQs!$D2<>"",COUNTIF(Routes!$D$4:$G$4,FAQs!$D2)>0)))),"●","") | F2: =IF(OR(ISNUMBER(SEARCH(","&F$1&",",","&SUBSTITUTE(FAQs!$G2," ","")&",")),AND(OR(FAQs!$E2="both",Routes!$C$5="both",FAQs!$E2=Routes!$C$5),OR(Routes!$D$5="ALL",COUNTIF(Routes!$D$5:$G$5,FAQs!$C2)>0,AND(FAQs!$D2<>"",COUNTIF(Routes!$D$5:$G$5,FAQs!$D2)>0)))),"●","") | G2: =IF(OR(ISNUMBER(SEARCH(","&G$1&",",","&SUBSTITUTE(FAQs!$G2," ","")&",")),AND(OR(FAQs!$E2="both",Routes!$C$6="both",FAQs!$E2=Routes!$C$6),OR(Routes!$D$6="ALL",COUNTIF(Routes!$D$6:$G$6,FAQs!$C2)>0,AND(FAQs!$D2<>"",COUNTIF(Routes!$D$6:$G$6,FAQs!$D2)>0)))),"●","") | H2: =IF(OR(ISNUMBER(SEARCH(","&H$1&",",","&SUBSTITUTE(FAQs!$G2," ","")&",")),AND(OR(FAQs!$E2="both",Routes!$C$7="both",FAQs!$E2=Routes!$C$7),OR(Routes!$D$7="ALL",COUNTIF(Routes!$D$7:$G$7,FAQs!$C2)>0,AND(FAQs!$D2<>"",COUNTIF(Routes!$D$7:$G$7,FAQs!$D2)>0)))),"●","") | I2: =IF(OR(ISNUMBER(SEARCH(","&I$1&",",","&SUBSTITUTE(FAQs!$G2," ","")&",")),AND(OR(FAQs!$E2="both",Routes!$C$8="both",FAQs!$E2=Routes!$C$8),OR(Routes!$D$8="ALL",COUNTIF(Routes!$D$8:$G$8,FAQs!$C2)>0,AND(FAQs!$D2<>"",COUNTIF(Routes!$D$8:$G$8,FAQs!$D2)>0)))),"●","") | J2: =IF(OR(ISNUMBER(SEARCH(","&J$1&",",","&SUBSTITUTE(FAQs!$G2," ","")&",")),AND(OR(FAQs!$E2="both",Routes!$C$9="both",FAQs!$E2=Routes!$C$9),OR(Routes!$D$9="ALL",COUNTIF(Routes!$D$9:$G$9,FAQs!$C2)>0,AND(FAQs!$D2<>"",COUNTIF(Routes!$D$9:$G$9,FAQs!$D2)>0)))),"●","") | K2: =IF(OR(ISNUMBER(SEARCH(","&K$1&",",","&SUBSTITUTE(FAQs!$G2," ","")&",")),AND(OR(FAQs!$E2="both",Routes!$C$10="both",FAQs!$E2=Routes!$C$10),OR(Routes!$D$10="ALL",COUNTIF(Routes!$D$10:$G$10,FAQs!$C2)>0,AND(FAQs!$D2<>"",COUNTIF(Routes!$D$10:$G$10,FAQs!$D2)>0)))),"●","") -> ● | L2: =IF(OR(ISNUMBER(SEARCH(","&L$1&",",","&SUBSTITUTE(FAQs!$G2," ","")&",")),AND(OR(FAQs!$E2="both",Routes!$C$11="both",FAQs!$E2=Routes!$C$11),OR(Routes!$D$11="ALL",COUNTIF(Routes!$D$11:$G$11,FAQs!$C2)>0,AND(FAQs!$D2<>"",COUNTIF(Routes!$D$11:$G$11,FAQs!$D2)>0)))),"●","") -> ● | M2: =IF(OR(ISNUMBER(SEARCH(","&M$1&",",","&SUBSTITUTE(FAQs!$G2," ","")&",")),AND(OR(FAQs!$E2="both",Routes!$C$12="both",FAQs!$E2=Routes!$C$12),OR(Routes!$D$12="ALL",COUNTIF(Routes!$D$12:$G$12,FAQs!$C2)>0,AND(FAQs!$D2<>"",COUNTIF(Routes!$D$12:$G$12,FAQs!$D2)>0)))),"●","") | N2: =IF(OR(ISNUMBER(SEARCH(","&N$1&",",","&SUBSTITUTE(FAQs!$G2," ","")&",")),AND(OR(FAQs!$E2="both",Routes!$C$13="both",FAQs!$E2=Routes!$C$13),OR(Routes!$D$13="ALL",COUNTIF(Routes!$D$13:$G$13,FAQs!$C2)>0,AND(FAQs!$D2<>"",COUNTIF(Routes!$D$13:$G$13,FAQs!$D2)>0)))),"●","") | O2: =IF(OR(ISNUMBER(SEARCH(","&O$1&",",","&SUBSTITUTE(FAQs!$G2," ","")&",")),AND(OR(FAQs!$E2="both",Routes!$C$14="both",FAQs!$E2=Routes!$C$14),OR(Routes!$D$14="ALL",COUNTIF(Routes!$D$14:$G$14,FAQs!$C2)>0,AND(FAQs!$D2<>"",COUNTIF(Routes!$D$14:$G$14,FAQs!$D2)>0)))),"●","") -> ● | P2: =IF(OR(ISNUMBER(SEARCH(","&P$1&",",","&SUBSTITUTE(FAQs!$G2," ","")&",")),AND(OR(FAQs!$E2="both",Routes!$C$15="both",FAQs!$E2=Routes!$C$15),OR(Routes!$D$15="ALL",COUNTIF(Routes!$D$15:$G$15,FAQs!$C2)>0,AND(FAQs!$D2<>"",COUNTIF(Routes!$D$15:$G$15,FAQs!$D2)>0)))),"●","") -> ● | Q2: =IF(OR(ISNUMBER(SEARCH(","&Q$1&",",","&SUBSTITUTE(FAQs!$G2," ","")&",")),AND(OR(FAQs!$E2="both",Routes!$C$16="both",FAQs!$E2=Routes!$C$16),OR(Routes!$D$16="ALL",COUNTIF(Routes!$D$16:$G$16,FAQs!$C2)>0,AND(FAQs!$D2<>"",COUNTIF(Routes!$D$16:$G$16,FAQs!$D2)>0)))),"●","") | R2: =IF(OR(ISNUMBER(SEARCH(","&R$1&",",","&SUBSTITUTE(FAQs!$G2," ","")&",")),AND(OR(FAQs!$E2="both",Routes!$C$17="both",FAQs!$E2=Routes!$C$17),OR(Routes!$D$17="ALL",COUNTIF(Routes!$D$17:$G$17,FAQs!$C2)>0,AND(FAQs!$D2<>"",COUNTIF(Routes!$D$17:$G$17,FAQs!$D2)>0)))),"●","") | S2: =IF(OR(ISNUMBER(SEARCH(","&S$1&",",","&SUBSTITUTE(FAQs!$G2," ","")&",")),AND(OR(FAQs!$E2="both",Routes!$C$18="both",FAQs!$E2=Routes!$C$18),OR(Routes!$D$18="ALL",COUNTIF(Routes!$D$18:$G$18,FAQs!$C2)>0,AND(FAQs!$D2<>"",COUNTIF(Routes!$D$18:$G$18,FAQs!$D2)>0)))),"●","") | T2: =IF(OR(ISNUMBER(SEARCH(","&T$1&",",","&SUBSTITUTE(FAQs!$G2," ","")&",")),AND(OR(FAQs!$E2="both",Routes!$C$19="both",FAQs!$E2=Routes!$C$19),OR(Routes!$D$19="ALL",COUNTIF(Routes!$D$19:$G$19,FAQs!$C2)>0,AND(FAQs!$D2<>"",COUNTIF(Routes!$D$19:$G$19,FAQs!$D2)>0)))),"●","") | U2: =COUNTIF(C2:T2,"●") -> 5
A3: =FAQs!A3 -> F02 | B3: =FAQs!H3 -> Can I check in online? | C3: =IF(OR(ISNUMBER(SEARCH(","&C$1&",",","&SUBSTITUTE(FAQs!$G3," ","")&",")),AND(OR(FAQs!$E3="both",Routes!$C$2="both",FAQs!$E3=Routes!$C$2),OR(Routes!$D$2="ALL",COUNTIF(Routes!$D$2:$G$2,FAQs!$C3)>0,AND(FAQs!$D3<>"",COUNTIF(Routes!$D$2:$G$2,FAQs!$D3)>0)))),"●","") -> ● | D3: =IF(OR(ISNUMBER(SEARCH(","&D$1&",",","&SUBSTITUTE(FAQs!$G3," ","")&",")),AND(OR(FAQs!$E3="both",Routes!$C$3="both",FAQs!$E3=Routes!$C$3),OR(Routes!$D$3="ALL",COUNTIF(Routes!$D$3:$G$3,FAQs!$C3)>0,AND(FAQs!$D3<>"",COUNTIF(Routes!$D$3:$G$3,FAQs!$D3)>0)))),"●","") | E3: =IF(OR(ISNUMBER(SEARCH(","&E$1&",",","&SUBSTITUTE(FAQs!$G3," ","")&",")),AND(OR(FAQs!$E3="both",Routes!$C$4="both",FAQs!$E3=Routes!$C$4),OR(Routes!$D$4="ALL",COUNTIF(Routes!$D$4:$G$4,FAQs!$C3)>0,AND(FAQs!$D3<>"",COUNTIF(Routes!$D$4:$G$4,FAQs!$D3)>0)))),"●","") | F3: =IF(OR(ISNUMBER(SEARCH(","&F$1&",",","&SUBSTITUTE(FAQs!$G3," ","")&",")),AND(OR(FAQs!$E3="both",Routes!$C$5="both",FAQs!$E3=Routes!$C$5),OR(Routes!$D$5="ALL",COUNTIF(Routes!$D$5:$G$5,FAQs!$C3)>0,AND(FAQs!$D3<>"",COUNTIF(Routes!$D$5:$G$5,FAQs!$D3)>0)))),"●","") | G3: =IF(OR(ISNUMBER(SEARCH(","&G$1&",",","&SUBSTITUTE(FAQs!$G3," ","")&",")),AND(OR(FAQs!$E3="both",Routes!$C$6="both",FAQs!$E3=Routes!$C$6),OR(Routes!$D$6="ALL",COUNTIF(Routes!$D$6:$G$6,FAQs!$C3)>0,AND(FAQs!$D3<>"",COUNTIF(Routes!$D$6:$G$6,FAQs!$D3)>0)))),"●","") | H3: =IF(OR(ISNUMBER(SEARCH(","&H$1&",",","&SUBSTITUTE(FAQs!$G3," ","")&",")),AND(OR(FAQs!$E3="both",Routes!$C$7="both",FAQs!$E3=Routes!$C$7),OR(Routes!$D$7="ALL",COUNTIF(Routes!$D$7:$G$7,FAQs!$C3)>0,AND(FAQs!$D3<>"",COUNTIF(Routes!$D$7:$G$7,FAQs!$D3)>0)))),"●","") | I3: =IF(OR(ISNUMBER(SEARCH(","&I$1&",",","&SUBSTITUTE(FAQs!$G3," ","")&",")),AND(OR(FAQs!$E3="both",Routes!$C$8="both",FAQs!$E3=Routes!$C$8),OR(Routes!$D$8="ALL",COUNTIF(Routes!$D$8:$G$8,FAQs!$C3)>0,AND(FAQs!$D3<>"",COUNTIF(Routes!$D$8:$G$8,FAQs!$D3)>0)))),"●","") | J3: =IF(OR(ISNUMBER(SEARCH(","&J$1&",",","&SUBSTITUTE(FAQs!$G3," ","")&",")),AND(OR(FAQs!$E3="both",Routes!$C$9="both",FAQs!$E3=Routes!$C$9),OR(Routes!$D$9="ALL",COUNTIF(Routes!$D$9:$G$9,FAQs!$C3)>0,AND(FAQs!$D3<>"",COUNTIF(Routes!$D$9:$G$9,FAQs!$D3)>0)))),"●","") | K3: =IF(OR(ISNUMBER(SEARCH(","&K$1&",",","&SUBSTITUTE(FAQs!$G3," ","")&",")),AND(OR(FAQs!$E3="both",Routes!$C$10="both",FAQs!$E3=Routes!$C$10),OR(Routes!$D$10="ALL",COUNTIF(Routes!$D$10:$G$10,FAQs!$C3)>0,AND(FAQs!$D3<>"",COUNTIF(Routes!$D$10:$G$10,FAQs!$D3)>0)))),"●","") -> ● | L3: =IF(OR(ISNUMBER(SEARCH(","&L$1&",",","&SUBSTITUTE(FAQs!$G3," ","")&",")),AND(OR(FAQs!$E3="both",Routes!$C$11="both",FAQs!$E3=Routes!$C$11),OR(Routes!$D$11="ALL",COUNTIF(Routes!$D$11:$G$11,FAQs!$C3)>0,AND(FAQs!$D3<>"",COUNTIF(Routes!$D$11:$G$11,FAQs!$D3)>0)))),"●","") -> ● | M3: =IF(OR(ISNUMBER(SEARCH(","&M$1&",",","&SUBSTITUTE(FAQs!$G3," ","")&",")),AND(OR(FAQs!$E3="both",Routes!$C$12="both",FAQs!$E3=Routes!$C$12),OR(Routes!$D$12="ALL",COUNTIF(Routes!$D$12:$G$12,FAQs!$C3)>0,AND(FAQs!$D3<>"",COUNTIF(Routes!$D$12:$G$12,FAQs!$D3)>0)))),"●","") | N3: =IF(OR(ISNUMBER(SEARCH(","&N$1&",",","&SUBSTITUTE(FAQs!$G3," ","")&",")),AND(OR(FAQs!$E3="both",Routes!$C$13="both",FAQs!$E3=Routes!$C$13),OR(Routes!$D$13="ALL",COUNTIF(Routes!$D$13:$G$13,FAQs!$C3)>0,AND(FAQs!$D3<>"",COUNTIF(Routes!$D$13:$G$13,FAQs!$D3)>0)))),"●","") | O3: =IF(OR(ISNUMBER(SEARCH(","&O$1&",",","&SUBSTITUTE(FAQs!$G3," ","")&",")),AND(OR(FAQs!$E3="both",Routes!$C$14="both",FAQs!$E3=Routes!$C$14),OR(Routes!$D$14="ALL",COUNTIF(Routes!$D$14:$G$14,FAQs!$C3)>0,AND(FAQs!$D3<>"",COUNTIF(Routes!$D$14:$G$14,FAQs!$D3)>0)))),"●","") -> ● | P3: =IF(OR(ISNUMBER(SEARCH(","&P$1&",",","&SUBSTITUTE(FAQs!$G3," ","")&",")),AND(OR(FAQs!$E3="both",Routes!$C$15="both",FAQs!$E3=Routes!$C$15),OR(Routes!$D$15="ALL",COUNTIF(Routes!$D$15:$G$15,FAQs!$C3)>0,AND(FAQs!$D3<>"",COUNTIF(Routes!$D$15:$G$15,FAQs!$D3)>0)))),"●","") -> ● | Q3: =IF(OR(ISNUMBER(SEARCH(","&Q$1&",",","&SUBSTITUTE(FAQs!$G3," ","")&",")),AND(OR(FAQs!$E3="both",Routes!$C$16="both",FAQs!$E3=Routes!$C$16),OR(Routes!$D$16="ALL",COUNTIF(Routes!$D$16:$G$16,FAQs!$C3)>0,AND(FAQs!$D3<>"",COUNTIF(Routes!$D$16:$G$16,FAQs!$D3)>0)))),"●","") | R3: =IF(OR(ISNUMBER(SEARCH(","&R$1&",",","&SUBSTITUTE(FAQs!$G3," ","")&",")),AND(OR(FAQs!$E3="both",Routes!$C$17="both",FAQs!$E3=Routes!$C$17),OR(Routes!$D$17="ALL",COUNTIF(Routes!$D$17:$G$17,FAQs!$C3)>0,AND(FAQs!$D3<>"",COUNTIF(Routes!$D$17:$G$17,FAQs!$D3)>0)))),"●","") | S3: =IF(OR(ISNUMBER(SEARCH(","&S$1&",",","&SUBSTITUTE(FAQs!$G3," ","")&",")),AND(OR(FAQs!$E3="both",Routes!$C$18="both",FAQs!$E3=Routes!$C$18),OR(Routes!$D$18="ALL",COUNTIF(Routes!$D$18:$G$18,FAQs!$C3)>0,AND(FAQs!$D3<>"",COUNTIF(Routes!$D$18:$G$18,FAQs!$D3)>0)))),"●","") | T3: =IF(OR(ISNUMBER(SEARCH(","&T$1&",",","&SUBSTITUTE(FAQs!$G3," ","")&",")),AND(OR(FAQs!$E3="both",Routes!$C$19="both",FAQs!$E3=Routes!$C$19),OR(Routes!$D$19="ALL",COUNTIF(Routes!$D$19:$G$19,FAQs!$C3)>0,AND(FAQs!$D3<>"",COUNTIF(Routes!$D$19:$G$19,FAQs!$D3)>0)))),"●","") | U3: =COUNTIF(C3:T3,"●") -> 5
A4: =FAQs!A4 -> F03 | B4: =FAQs!H4 -> Can I leave my luggage before check-in? | C4: =IF(OR(ISNUMBER(SEARCH(","&C$1&",",","&SUBSTITUTE(FAQs!$G4," ","")&",")),AND(OR(FAQs!$E4="both",Routes!$C$2="both",FAQs!$E4=Routes!$C$2),OR(Routes!$D$2="ALL",COUNTIF(Routes!$D$2:$G$2,FAQs!$C4)>0,AND(FAQs!$D4<>"",COUNTIF(Routes!$D$2:$G$2,FAQs!$D4)>0)))),"●","") -> ● | D4: =IF(OR(ISNUMBER(SEARCH(","&D$1&",",","&SUBSTITUTE(FAQs!$G4," ","")&",")),AND(OR(FAQs!$E4="both",Routes!$C$3="both",FAQs!$E4=Routes!$C$3),OR(Routes!$D$3="ALL",COUNTIF(Routes!$D$3:$G$3,FAQs!$C4)>0,AND(FAQs!$D4<>"",COUNTIF(Routes!$D$3:$G$3,FAQs!$D4)>0)))),"●","") | E4: =IF(OR(ISNUMBER(SEARCH(","&E$1&",",","&SUBSTITUTE(FAQs!$G4," ","")&",")),AND(OR(FAQs!$E4="both",Routes!$C$4="both",FAQs!$E4=Routes!$C$4),OR(Routes!$D$4="ALL",COUNTIF(Routes!$D$4:$G$4,FAQs!$C4)>0,AND(FAQs!$D4<>"",COUNTIF(Routes!$D$4:$G$4,FAQs!$D4)>0)))),"●","") | F4: =IF(OR(ISNUMBER(SEARCH(","&F$1&",",","&SUBSTITUTE(FAQs!$G4," ","")&",")),AND(OR(FAQs!$E4="both",Routes!$C$5="both",FAQs!$E4=Routes!$C$5),OR(Routes!$D$5="ALL",COUNTIF(Routes!$D$5:$G$5,FAQs!$C4)>0,AND(FAQs!$D4<>"",COUNTIF(Routes!$D$5:$G$5,FAQs!$D4)>0)))),"●","") | G4: =IF(OR(ISNUMBER(SEARCH(","&G$1&",",","&SUBSTITUTE(FAQs!$G4," ","")&",")),AND(OR(FAQs!$E4="both",Routes!$C$6="both",FAQs!$E4=Routes!$C$6),OR(Routes!$D$6="ALL",COUNTIF(Routes!$D$6:$G$6,FAQs!$C4)>0,AND(FAQs!$D4<>"",COUNTIF(Routes!$D$6:$G$6,FAQs!$D4)>0)))),"●","") | H4: =IF(OR(ISNUMBER(SEARCH(","&H$1&",",","&SUBSTITUTE(FAQs!$G4," ","")&",")),AND(OR(FAQs!$E4="both",Routes!$C$7="both",FAQs!$E4=Routes!$C$7),OR(Routes!$D$7="ALL",COUNTIF(Routes!$D$7:$G$7,FAQs!$C4)>0,AND(FAQs!$D4<>"",COUNTIF(Routes!$D$7:$G$7,FAQs!$D4)>0)))),"●","") | I4: =IF(OR(ISNUMBER(SEARCH(","&I$1&",",","&SUBSTITUTE(FAQs!$G4," ","")&",")),AND(OR(FAQs!$E4="both",Routes!$C$8="both",FAQs!$E4=Routes!$C$8),OR(Routes!$D$8="ALL",COUNTIF(Routes!$D$8:$G$8,FAQs!$C4)>0,AND(FAQs!$D4<>"",COUNTIF(Routes!$D$8:$G$8,FAQs!$D4)>0)))),"●","") | J4: =IF(OR(ISNUMBER(SEARCH(","&J$1&",",","&SUBSTITUTE(FAQs!$G4," ","")&",")),AND(OR(FAQs!$E4="both",Routes!$C$9="both",FAQs!$E4=Routes!$C$9),OR(Routes!$D$9="ALL",COUNTIF(Routes!$D$9:$G$9,FAQs!$C4)>0,AND(FAQs!$D4<>"",COUNTIF(Routes!$D$9:$G$9,FAQs!$D4)>0)))),"●","") | K4: =IF(OR(ISNUMBER(SEARCH(","&K$1&",",","&SUBSTITUTE(FAQs!$G4," ","")&",")),AND(OR(FAQs!$E4="both",Routes!$C$10="both",FAQs!$E4=Routes!$C$10),OR(Routes!$D$10="ALL",COUNTIF(Routes!$D$10:$G$10,FAQs!$C4)>0,AND(FAQs!$D4<>"",COUNTIF(Routes!$D$10:$G$10,FAQs!$D4)>0)))),"●","") -> ● | L4: =IF(OR(ISNUMBER(SEARCH(","&L$1&",",","&SUBSTITUTE(FAQs!$G4," ","")&",")),AND(OR(FAQs!$E4="both",Routes!$C$11="both",FAQs!$E4=Routes!$C$11),OR(Routes!$D$11="ALL",COUNTIF(Routes!$D$11:$G$11,FAQs!$C4)>0,AND(FAQs!$D4<>"",COUNTIF(Routes!$D$11:$G$11,FAQs!$D4)>0)))),"●","") -> ● | M4: =IF(OR(ISNUMBER(SEARCH(","&M$1&",",","&SUBSTITUTE(FAQs!$G4," ","")&",")),AND(OR(FAQs!$E4="both",Routes!$C$12="both",FAQs!$E4=Routes!$C$12),OR(Routes!$D$12="ALL",COUNTIF(Routes!$D$12:$G$12,FAQs!$C4)>0,AND(FAQs!$D4<>"",COUNTIF(Routes!$D$12:$G$12,FAQs!$D4)>0)))),"●","") | N4: =IF(OR(ISNUMBER(SEARCH(","&N$1&",",","&SUBSTITUTE(FAQs!$G4," ","")&",")),AND(OR(FAQs!$E4="both",Routes!$C$13="both",FAQs!$E4=Routes!$C$13),OR(Routes!$D$13="ALL",COUNTIF(Routes!$D$13:$G$13,FAQs!$C4)>0,AND(FAQs!$D4<>"",COUNTIF(Routes!$D$13:$G$13,FAQs!$D4)>0)))),"●","") | O4: =IF(OR(ISNUMBER(SEARCH(","&O$1&",",","&SUBSTITUTE(FAQs!$G4," ","")&",")),AND(OR(FAQs!$E4="both",Routes!$C$14="both",FAQs!$E4=Routes!$C$14),OR(Routes!$D$14="ALL",COUNTIF(Routes!$D$14:$G$14,FAQs!$C4)>0,AND(FAQs!$D4<>"",COUNTIF(Routes!$D$14:$G$14,FAQs!$D4)>0)))),"●","") -> ● | P4: =IF(OR(ISNUMBER(SEARCH(","&P$1&",",","&SUBSTITUTE(FAQs!$G4," ","")&",")),AND(OR(FAQs!$E4="both",Routes!$C$15="both",FAQs!$E4=Routes!$C$15),OR(Routes!$D$15="ALL",COUNTIF(Routes!$D$15:$G$15,FAQs!$C4)>0,AND(FAQs!$D4<>"",COUNTIF(Routes!$D$15:$G$15,FAQs!$D4)>0)))),"●","") -> ● | Q4: =IF(OR(ISNUMBER(SEARCH(","&Q$1&",",","&SUBSTITUTE(FAQs!$G4," ","")&",")),AND(OR(FAQs!$E4="both",Routes!$C$16="both",FAQs!$E4=Routes!$C$16),OR(Routes!$D$16="ALL",COUNTIF(Routes!$D$16:$G$16,FAQs!$C4)>0,AND(FAQs!$D4<>"",COUNTIF(Routes!$D$16:$G$16,FAQs!$D4)>0)))),"●","") | R4: =IF(OR(ISNUMBER(SEARCH(","&R$1&",",","&SUBSTITUTE(FAQs!$G4," ","")&",")),AND(OR(FAQs!$E4="both",Routes!$C$17="both",FAQs!$E4=Routes!$C$17),OR(Routes!$D$17="ALL",COUNTIF(Routes!$D$17:$G$17,FAQs!$C4)>0,AND(FAQs!$D4<>"",COUNTIF(Routes!$D$17:$G$17,FAQs!$D4)>0)))),"●","") | S4: =IF(OR(ISNUMBER(SEARCH(","&S$1&",",","&SUBSTITUTE(FAQs!$G4," ","")&",")),AND(OR(FAQs!$E4="both",Routes!$C$18="both",FAQs!$E4=Routes!$C$18),OR(Routes!$D$18="ALL",COUNTIF(Routes!$D$18:$G$18,FAQs!$C4)>0,AND(FAQs!$D4<>"",COUNTIF(Routes!$D$18:$G$18,FAQs!$D4)>0)))),"●","") | T4: =IF(OR(ISNUMBER(SEARCH(","&T$1&",",","&SUBSTITUTE(FAQs!$G4," ","")&",")),AND(OR(FAQs!$E4="both",Routes!$C$19="both",FAQs!$E4=Routes!$C$19),OR(Routes!$D$19="ALL",COUNTIF(Routes!$D$19:$G$19,FAQs!$C4)>0,AND(FAQs!$D4<>"",COUNTIF(Routes!$D$19:$G$19,FAQs!$D4)>0)))),"●","") | U4: =COUNTIF(C4:T4,"●") -> 5
